Workbook

Sheet Resumen piloto
A1: NÉVOLA · VIVIENDA PILOTO EN SISTEMA MODULAR · ESTUDIO DE COSTES
A2: Pareada tipo de 148,30 m². Proyecto de ejecución de julio de 2026. Sin IVA. Dos escenarios: piloto como primera unidad de la serie, o piloto aislado.
A4: Concepto | B4: Piloto dentro de la serie | C4: Piloto aislado
A5: Estructura y envolvente modular (hoja Sistema modular) | B5: ='Sistema modular'!$E$19 | C5: ='Sistema modular'!$E$19
A6: Partidas que se ejecutan igual (proyecto) | B6: ='Partidas iguales'!$C$16*(1-Supuestos!$B$20) | C6: ='Partidas iguales'!$C$16*(1-Supuestos!$B$20)
A7: Sobrecoste de primera unidad en mano de obra de fábrica | B7: =(Acero!$E$42*(Supuestos!$B$6-0.90-0.24)+479.59*Supuestos!$B$8*Supuestos!$B$7)*Supuestos!$B$21 | C7: =(Acero!$E$42*(Supuestos!$B$6-0.90-0.24)+479.59*Supuestos!$B$8*Supuestos!$B$7)*Supuestos!$B$21
A8: Transporte de 6 módulos + pieza de vuelo | B8: =6*Supuestos!$B$22*(1+Supuestos!$B$5)+Supuestos!$B$23 | C8: =6*Supuestos!$B$22*(1+Supuestos!$B$5)+Supuestos!$B$23
A9: Grúa (jornada completa) | B9: =Supuestos!$B$24*(1+Supuestos!$B$5) | C9: =Supuestos!$B$24*(1+Supuestos!$B$5)
A10: Montaje en parcela | B10: =Supuestos!$B$25*Supuestos!$B$7*(1+Supuestos!$B$26) | C10: =Supuestos!$B$25*Supuestos!$B$7*(1+Supuestos!$B$26)
A11: Ingeniería: cálculo modular y proyecto de fabricación | B11: =Supuestos!$B$27/16 | C11: =Supuestos!$B$27
A12: Gastos fijos de fábrica imputados | B12: =Supuestos!$B$28/Supuestos!$B$29 | C12: =Supuestos!$B$28*Supuestos!$B$30
A13: COSTE DEL PILOTO | B13: =SUM(B5:B12) | C13: =SUM(C5:C12)
A14: Margen RG21 | B14: =B13*Supuestos!$B$31 | C14: =C13*Supuestos!$B$31
A15: PRECIO DEL PILOTO (sin IVA) | B15: =B13+B14 | C15: =C13+C14
A16: €/m² construido | B16: =B15/148.3 | C16: =C15/148.3
A18: Referencia: contrata tradicional del mismo alcance (PEM del proyecto × 1,19) | B18: =(51496.54+'Partidas iguales'!$C$16)*(1+Supuestos!$B$32) | C18: =(51496.54+'Partidas iguales'!$C$16)*(1+Supuestos!$B$32)
A19: Diferencia con la contrata tradicional | B19: =B15-B18 | C19: =C15-C18
A20: Precio del piloto en la propuesta integral | B20: =225400 | C20: =273600
A23: LECTURA
A24: 1. El acero medido sobre la modulación sale a 13.216 kg (89,1 kg/m²), en línea con Mahón (89 kg/m²). Es el 30 % del coste del sistema modular.
A25: 2. La fachada medida (166,2 m² opacos) coincide con la del proyecto (166,5 m²). En pareadas, cada vivienda cierra sus módulos: 68,3 m² de medianera con panel.
A26: 3. «Piloto dentro de la serie» reparte la ingeniería entre 16 y carga los gastos fijos al ritmo de 2 viviendas/mes. «Piloto aislado» carga toda la ingeniería y 1,5 meses de fábrica: es el coste real si después no hay serie.
A27: 4. Ahorros posibles que no están aplicados: rediseño del módulo (cada 10 kg/m² ≈ 3.900 €), un 8–12 % en las partidas iguales por fabricar en taller, y medianera compartida entre las dos viviendas del pareado.

Sheet Supuestos
A1: SUPUESTOS DEL ESTUDIO DEL PILOTO
A2: Celdas rosadas con cifra en rojo minio = editables. Costes reales de fábrica de 2026; el margen se aplica una vez en el Resumen.
A4: Concepto | B4: Valor | C4: Origen
A5: Actualización de costes 2024→2026 | B5: 0.12 | C5: ACR 2025 +5,46 %; Banco de España abril 2026 +3,5 %
A6: Coste del acero fabricado (€/kg): material, corte, soldadura, imprimación y pintura | B6: 2.6 | C6: Material 0,80 €/kg en 2024 (Mahón) + soldadura propia
A7: Mano de obra de fábrica (€/h) | B7: 23 | C7: Nóminas DWHAI sep–nov 2024
A8: Horas de montaje de panel por m² | B8: 0.5 | C8: Estimado
A9: Merma de panel | B9: 0.05
A10: Panel Tabihaus 8+50+8 (coste 2024 €/m²) | B10: 42 | C10: Resumen Mahón 21/11/2024
A11: Panel Tabihaus 8+65+8 (coste 2024 €/m²) | B11: 52 | C11: Resumen Mahón 21/11/2024
A12: Panel Tabihaus 8+120+8 (coste 2024 €/m²) | B12: 64 | C12: Resumen Mahón 21/11/2024
A13: Trasdosado interior con aislamiento (€/m²) | B13: 31.85 | C13: Precio del proyecto (Knauf W625)
A14: Suplemento de aislamiento para U = 0,20 en fachada (€/m²) | B14: 10 | C14: PET 40 mm
A15: Acabado exterior sobre panel (€/m²) | B15: 45 | C15: ESTIMADO: placa de cemento + monocapa / aplacado. Pedir precio
A16: Sistema de cubierta no transitable sobre panel (€/m²) | B16: 88.8 | C16: Precio del proyecto (D08PD002)
A17: Sistema de cubierta transitable sobre panel (€/m²) | B17: 97.54 | C17: Precio del proyecto (QAB010b)
A18: Sellado y tapajuntas entre módulos (€/m) | B18: 25 | C18: Estimado
A19: Colectores suspendidos bajo planta baja (€) | B19: 941.45 | C19: Proyecto / 16
A20: Ahorro de fábrica sobre las partidas que se hacen igual | B20: 0 | C20: Prudente en el piloto: 0 %
A21: Sobrecoste de primera unidad sobre mano de obra de fábrica | B21: 0.15 | C21: Curva de aprendizaje del prototipo
... A25: Horas de montaje en parcela | B25: 192 | C25: 3 operarios × 8 días (primera unidad)
A26: Dietas y desplazamientos sobre montaje | B26: 0.15
A27: Ingeniería: cálculo modular y proyecto de fabricación (€) | B27: 25000 | C27: Estimado, para toda la serie
A28: Gastos fijos de fábrica sin mano de obra (€/mes) | B28: 20430 | C28: Nave, oficina técnica, gestión, suministros, seguros
A29: Viviendas al mes en serie | B29: 2
A30: Meses de fábrica imputados al piloto si se fabrica aislado | B30: 1.5 | C30: Primera unidad sin otras obras en la nave
A31: Margen RG21 (GG + beneficio) | B31: 0.1
A32: GG + BI de una contrata tradicional sobre PEM | B32: 0.19

Sheet Módulos
A1: MODULACIÓN DE LA VIVIENDA PAREADA (piloto)
A2: Seis módulos de acero, tres por planta, con juntas alineadas con tabiques: anchos de 3,20 / 2,30 / 2,35 m (juntas a 3,20 y 5,50 m en planta baja). La planta primera vuela 0,60 m en frente y lateral; el vuelo lateral es una pieza aparte (V) que se atornilla al M4 en parcela. Exige desplazar 0,30 m el tabique del dormitorio 1 (pasa a 8,70 m²).
A4: Módulo | B4: Planta | C4: Ancho (m) | D4: Largo (m) | E4: Alto (m) | F4: Superficie (m²) | G4: Qué contiene
A5: M1 | B5: PB | C5: 3.2 | D5: 9.5 | E5: 3.05 | F5: =C5*D5 | G5: Dormitorio 1, cocina, salón
A6: M2 | B6: PB | C6: 2.3 | D6: 9.5 | E6: 3.05 | F6: =C6*D6 | G6: Vestíbulo, escalera, salón
A7: M3 | B7: PB | C7: 2.35 | D7: 9.5 | E7: 3.05 | F7: =C7*D7 | G7: Baño 1, lavadero, escalera, salón (medianera)
A8: M4 | B8: P1 | C8: 3.2 | D8: 8.47 | E8: 3.05 | F8: =C8*D8 | G8: Dormitorio 3, baño 2, dormitorio principal · vuelo frontal 0,60
A9: M5 | B9: P1 | C9: 2.3 | D9: 8.47 | E9: 3.05 | F9: =C9*D9 | G9: Dormitorio 2, distribuidor, escalera, dormitorio principal
A10: M6 | B10: P1 | C10: 2.35 | D10: 10.1 | E10: 3.05 | F10: =C10*D10 | G10: Dormitorio 2, escalera, vestidor, baño principal (medianera)
A11: V | B11: P1 | C11: 0.6 | D11: 8.47 | E11: 0.3 | F11: =C11*D11 | G11: Pieza de vuelo lateral, se monta en parcela (no es módulo volumétrico)
A12: TOTAL | F12: =SUM(F5:F11)
A14: Transporte: el módulo más alto mide unos 3,05 m; en góndola rebajada (0,85 m) queda en ≈ 3,90 m, dentro del límite de 4,00 m. Ningún módulo pasa de 3,20 m de ancho: todos viajan sin transporte especial. La pieza de vuelo va aparte.

Sheet Acero
A1: MEDICIÓN DE ACERO POR ELEMENTO (tipología del proyecto de Mahón 182)
A2: Mismos perfiles y cuantías de correas y secundaria que Mahón; marcos, pilares y vuelos medidos sobre la modulación de Névola.
A4: Módulo | B4: Elemento | C4: Medición (m) | D4: kg/m | E4: kg
A5: M1 | B5: Vigas de marco IPE 200 (suelo y techo) | C5: 50.8 | D5: 22.96 | E5: =C5*D5
A6: M1 | B6: Pilares IPE 160 (6 ud × 2.65 m) | C6: 15.9 | D6: 16.2 | E6: =C6*D6
A7: M1 | B7: Correas de suelo HEA 100 (0,64 m/m², como Mahón) | C7: 19.46 | D7: 16.7 | E7: =C7*D7
A8: M1 | B8: Correas de techo SHS 60.40.3 (1,94 m/m², como Mahón) | C8: 58.98 | D8: 4.42 | E8: =C8*D8
A9: M1 | B9: Angular L 80.8 de apoyo de panel (2,34 kg/m², como Mahón) | C9: 30.4 | D9: 2.34 | E9: =C9*D9
A10: M2 | B10: Vigas de marco IPE 200 (suelo y techo) | C10: 47.2 | D10: 22.96 | E10: =C10*D10
A11: M2 | B11: Pilares IPE 160 (6 ud × 2.65 m) | C11: 15.9 | D11: 16.2 | E11: =C11*D11
A12: M2 | B12: Correas de suelo HEA 100 (0,64 m/m², como Mahón) | C12: 13.98 | D12: 16.7 | E12: =C12*D12
A13: M2 | B13: Correas de techo SHS 60.40.3 (1,94 m/m², como Mahón) | C13: 42.39 | D13: 4.42 | E13: =C13*D13
A14: M2 | B14: Angular L 80.8 de apoyo de panel (2,34 kg/m², como Mahón) | C14: 21.85 | D14: 2.34 | E14: =C14*D14
A15: M3 | B15: Vigas de marco IPE 200 (suelo y techo) | C15: 47.4 | D15: 22.96 | E15: =C15*D15
A16: M3 | B16: Pilares IPE 160 (6 ud × 2.65 m) | C16: 15.9 | D16: 16.2 | E16: =C16*D16
... A41: General | B41: Refuerzos, remates y pletinas de arriostramiento (5,6 kg/m², como Mahón) | C41: 144.88 | D41: 5.59 | E41: =C41*D41
B42: TOTAL ACERO | E42: =SUM(E5:E41)
B43: kg por m² construido (148,30 m²) | E43: =E42/148.3
B44: Referencia Mahón (proyecto 182): 13.516 kg / 151,2 m² = 89 kg/m²

Sheet Sistema modular
A1: COSTE DEL SISTEMA MODULAR DEL PILOTO (estructura, envolvente y forjados)
A2: Mediciones sobre la modulación. Sustituye estructura de hormigón, solera Cáviti, cubiertas, ladrillo, enfoscados, monocapa y aislamientos del proyecto.
A4: Partida | B4: Ud | C4: Medición | D4: Coste unitario | E4: Importe | F4: Medición / precio
A5: Estructura de acero de los 6 módulos (hoja Acero) | B5: kg | C5: =Acero!$E$42 | D5: =Supuestos!$B$6 | E5: =C5*D5
A6: Panel 8+50+8 en fachadas opacas (con petos) | B6: m² | C6: 166.17 | D6: =(Supuestos!$B$10*(1+Supuestos!$B$5)*(1+Supuestos!$B$9)+Supuestos!$B$8*Supuestos!$B$7) | E6: =C6*D6 | F6: Fachada bruta 188,2 m² − 22 m² de huecos (proyecto: 166,5 m²)
A7: Panel 8+50+8 en medianera (cada vivienda cierra sus módulos) | B7: m² | C7: 68.3 | D7: =(Supuestos!$B$10*(1+Supuestos!$B$5)*(1+Supuestos!$B$9)+Supuestos!$B$8*Supuestos!$B$7) | E7: =C7*D7 | F7: Planta baja 29,9 + planta primera 38,4 m²
A8: Panel 8+50+8 en la cara inferior de los vuelos | B8: m² | C8: 10.77 | D8: =(Supuestos!$B$10*(1+Supuestos!$B$5)*(1+Supuestos!$B$9)+Supuestos!$B$8*Supuestos!$B$7) | E8: =C8*D8 | F8: Vuelo de 0,60 m en frente y lateral
A9: Trasdosado interior con aislamiento (fachada y medianera) | B9: m² | C9: 234.48 | D9: =Supuestos!$B$13 | E9: =C9*D9 | F9: Precio del proyecto
A10: Suplemento de aislamiento para U = 0,20 | B10: m² | C10: 166.17 | D10: =Supuestos!$B$14 | E10: =C10*D10
A11: Acabado exterior sobre panel (fachadas y vuelos) | B11: m² | C11: 176.94 | D11: =Supuestos!$B$15 | E11: =C11*D11 | F11: ESTIMADO
A12: Panel 8+65+8 de cubierta (planta primera + terraza) | B12: m² | C12: 84.37 | D12: =(Supuestos!$B$11*(1+Supuestos!$B$5)*(1+Supuestos!$B$9)+Supuestos!$B$8*Supuestos!$B$7) | E12: =C12*D12
A13: Sistema de cubierta no transitable sobre panel | B13: m² | C13: 75.39 | D13: =Supuestos!$B$16 | E13: =C13*D13 | F13: Precio del proyecto
A14: Sistema de cubierta transitable en terraza | B14: m² | C14: 8.98 | D14: =Supuestos!$B$17 | E14: =C14*D14 | F14: Precio del proyecto
A15: Panel 8+120+8 en suelo de planta baja | B15: m² | C15: 74.58 | D15: =(Supuestos!$B$12*(1+Supuestos!$B$5)*(1+Supuestos!$B$9)+Supuestos!$B$8*Supuestos!$B$7) | E15: =C15*D15 | F15: Sustituye a la solera Cáviti
A16: Panel 8+65+8 en suelo de planta primera | B16: m² | C16: 75.39 | D16: =(Supuestos!$B$11*(1+Supuestos!$B$5)*(1+Supuestos!$B$9)+Supuestos!$B$8*Supuestos!$B$7) | E16: =C16*D16 | F16: Sustituye al forjado unidireccional
A17: Sellado y tapajuntas entre módulos | B17: m | C17: 73.04 | D17: =Supuestos!$B$18 | E17: =C17*D17 | F17: Juntas verticales y perímetro entre plantas
A18: Colectores suspendidos bajo planta baja | B18: ud | C18: 1 | D18: =Supuestos!$B$19 | E18: =C18*D18 | F18: Como el proyecto
A19: TOTAL SISTEMA MODULAR | E19: =SUM(E5:E18)

Sheet Partidas iguales
A1: PARTIDAS QUE SE EJECUTAN IGUAL (mediciones y precios del proyecto, por vivienda)
A2: Instalaciones, carpinterías, acabados, sanitarios y pruebas. Importe del proyecto / 16 viviendas.
A4: Capítulo | B4: Descripción | C4: PEM por vivienda
A5: C.03 | B5: Saneamiento interior (bajantes) | C5: 572.86
A6: C.07 | B6: Impermeabilización de zonas húmedas y aislamiento acústico | C6: 849.18
A7: C.08 | B7: Tabiquería, falsos techos y mampara | C7: 9471.83
A8: C.09 | B8: Alicatados, solados, peldaños, vierteaguas y albardillas | C8: 10163.61
A9: C.10 | B9: Carpintería interior y armarios | C9: 3924.09
A10: C.11 | B10: Carpintería exterior, recercados y barandillas | C10: 12377.21
A11: C.12 | B11: Pintura | C11: 3748.1
A12: C.13 | B12: Electricidad y telecomunicaciones | C12: 13180.5
A13: C.14 | B13: Fontanería y aparatos sanitarios | C13: 5829.69
A14: C.15 | B14: Climatización, ACS y ventilación | C14: 18715.51
A15: C.19 | B15: Pruebas de servicio y de estanqueidad | C15: 532.8
B16: TOTAL | C16: =SUM(C5:C15)

Sheet Ahorros por calidades
A1: MEMORIA DE CALIDADES DEL PROYECTO FRENTE A ALTERNATIVAS DE AHORRO (por vivienda pareada)
A2: S = sistema modular o duplicidad (no cambia calidades) · M = marca o gama equivalente («o similar») · A = alcance de la memoria comercial. Ahorros estimados: confirmar con ofertas.
A4: Capítulo | B4: Partida | C4: Proyecto | D4: €/viv. proyecto | E4: Alternativa | F4: Ahorro €/viv. | G4: Tipo
A5: Climatización | B5: Aerotermia | C5: Vaillant aroTHERM plus uniTOWER biblock, 10,1 kW, A+++ | D5: 8376 | E5: Panasonic Aquarea All in One o LG Therma V con depósito de 200 l, dimensionada a 8 kW (vivienda A+ de 125 m² útiles) | F5: 2000 | G5: M
A6: Climatización | B6: Bomba circuladora | C6: Ebara Ego Easy 25/80 aparte | D6: 595 | E6: La integrada en el módulo hidráulico de la aerotermia (un solo circuito con colectores) | F6: 400 | G6: S
A7: Climatización | B7: Suelo radiante | C7: Polytherm Premium, panel termoconformado (35,86 €/m²) | D7: 4483 | E7: Sistema estándar de panel liso (Uponor, Orkli o Giacomini) a unos 30 €/m² | F7: 750 | G7: M
A8: Tabiquería | B8: Tabiques interiores | C8: Knauf W112, doble placa por cara (29,94 €/m²) | D8: 3910 | E8: Placa sencilla de 15 mm por cara (W111) entre estancias de la misma vivienda; W112 solo en baños y escalera | F8: 1000 | G8: A
A9: Techos | B9: Falso techo de cuartos secos y húmedos | C9: Knauf D47 suspendido con maestras (27,74 y 31,01 €/m²) | D9: 3447 | E9: Placa atornillada directamente a las correas del techo del módulo, sin estructura suspendida | F9: 1180 | G9: S
A10: Techos | B10: Falso techo exterior de placa de cemento | C10: Aquapanel Outdoor bajo vuelos (101,73 €/m²) | D10: 992 | E10: Ya incluido: el vuelo del módulo lleva panel con acabado exterior | F10: 992 | G10: S
A11: Fachada | B11: Aplacado de gres en fachada | C11: Porcelánico en capa fina sobre mortero (48,34 €/m², 31 m²) | D11: 1504 | E11: Se mantiene el aplacado y se descuenta esa superficie del acabado exterior del panel (no duplicar) | F11: 1400 | G11: S
A12: Electricidad | B12: Red de toma de tierra de estructura | C12: Cable de 35 mm² soldado a la armadura de cada zapata (40,65 m) | D12: 2061 | E12: Conexión equipotencial de los marcos de acero al anillo de cimentación del promotor | F12: 1200 | G12: S
A13: Electricidad | B13: Punto de recarga de vehículo | C13: Caja de recarga 2,3 kW instalada | D13: 1242 | E13: Preinstalación (canalización y línea), que es lo que promete la memoria comercial | F13: 890 | G13: A
A14: Electricidad | B14: Cuadro general | C14: Electrificación elevada, 24 elementos, 12 circuitos | D14: 1171 | E14: Mismo esquema montado en fábrica con aparamenta de gama media (Hager, Schneider Resi9) | F14: 320 | G14: M
A15: Electricidad | B15: Videoportero | C15: Digital 3 hilos + coaxial, monitor b/n 4" | D15: 730 | E15: Kit de 2 hilos en color (Fermax o Golmar) | F15: 280 | G15: M
A16: Pavimentos | B16: Tarima laminada | C16: Terhürne Comfloor Akustec AC5/32, 8,5 mm (36,32 €/m²) | D16: 3245 | E16: Laminado AC5 de 8 mm de fabricante nacional (Finsa, Faus) a unos 28 €/m² | F16: 715 | G16: M
... A21: Carpintería exterior | B21: Barandilla de terraza | C21: Comenza GlassFit SV-1401 Top (197,86 €/m) | D21: 1408 | E21: Vidrio laminar con perfil de base genérico, misma imagen | F21: 340 | G21: M
E22: Ahorro por sistema modular y duplicidades (S) | F22: =SUMIF(G5:G21,"S",F5:F21)
E23: Ahorro por marca o gama equivalente (M) | F23: =SUMIF(G5:G21,"M",F5:F21)
E24: Ahorro por alcance (A) | F24: =SUMIF(G5:G21,"A",F5:F21)
E25: AHORRO TOTAL DE COSTE POR VIVIENDA | F25: =SUM(F5:F21)
E26: Bajada de precio con margen | F26: =F25*(1+Supuestos!$B$31)
E27: Precio del piloto (serie) con los ahorros | F27: ='Resumen piloto'!B15-F26

Sheet Escenarios de margen
A1: ESCENARIOS DE MARGEN Y PARTIDAS QUE FALTAN EN EL COSTE
A2: Celdas rosadas con cifra en rojo minio = editables. El coste del modelo ya incluye la mano de obra de fábrica y de montaje a coste empresa (nómina + Seguridad Social, 23 €/h de 2024).
A4: Supuesto | B4: Valor | F4: Origen
A5: Operarios de fábrica al arrancar | B5: 6 | F5: Iván, 13/10/2026
A6: Horas productivas por operario y mes | B6: 146.7 | F6: 1.760 h/año / 12
A7: Nómina + Seguridad Social con 9 operarios (€/mes, 2024) | B7: 28250 | F7: Nóminas DWHAI sep–nov 2024
A8: Subida salarial 2024→2026 (convenio del metal y SMI) | B8: 0.08 | F8: ESTIMADO: confirmar con el convenio aplicable
A9: Estructura de RG21: dirección, comercial y administración, con SS (€/mes) | B9: 8000 | F9: Iván, 13/10/2026
A10: Garantía y posventa (% del coste) | B10: 0.01 | F10: Habitual 0,5–1,5 %
A11: Imprevistos (% del coste) | B11: 0.03 | F11: Primera serie: 3–5 %
A12: Coste de la pareada en serie (modelo, a 2 viviendas/mes) | B12: 190091 | F12: Presupuesto técnico a 90 kg/m²: 209.100 € / 1,10
A13: Coste de la aislada en serie (modelo, a 2 viviendas/mes) | B13: 194636 | F13: 214.100 € / 1,10
A14: Precio ofertado del piloto (dentro de la serie) | B14: 225400 | F14: Propuesta integral, 14/10/2026: 10 % sobre el coste del modelo
A15: Precio ofertado del piloto aislado | B15: 273600 | F15: Propuesta integral, 14/10/2026
A16: Precio ofertado de la pareada en serie | B16: 209100 | F16: Propuesta integral, 14/10/2026
A17: Precio ofertado de la aislada en serie | B17: 214100 | F17: Propuesta integral, 14/10/2026
A19: Horas de fábrica por vivienda (acero y panel) | B19: =(Acero!$E$42*(Supuestos!$B$6-0.90-0.24)+479.59*Supuestos!$B$8*Supuestos!$B$7)/Supuestos!$B$7 | F19: Sale del modelo
A20: Viviendas al mes con esa plantilla | B20: =$B$5*$B$6/$B$19 | F20: El modelo supone 2 al mes
A21: Meses de fábrica para las 16 viviendas | B21: =16/$B$20
A22: Nómina + SS de la plantilla de arranque (€/mes, 2024) | B22: =$B$7*$B$5/9 | F22: Proporcional a 9 operarios
A24: PARTIDAS QUE FALTAN O ESTÁN A PRECIO DE 2024 (por vivienda)
A25: Concepto | B25: Piloto en serie | C25: Piloto aislado | D25: Pareada en serie | E25: Aislada en serie | F25: Comentario
A26: Mano de obra de fábrica y montaje a salarios de 2026 | B26: =((Acero!$E$42*(Supuestos!$B$6-0.90-0.24)+479.59*Supuestos!$B$8*Supuestos!$B$7)+Supuestos!$B$25*Supuestos!$B$7*(1+Supuestos!$B$26))*$B$8 | C26: =((Acero!$E$42*(Supuestos!$B$6-0.90-0.24)+479.59*Supuestos!$B$8*Supuestos!$B$7)+Supuestos!$B$25*Supuestos!$B$7*(1+Supuestos!$B$26))*$B$8 | D26: =((Acero!$E$42*(Supuestos!$B$6-0.90-0.24)+479.59*Supuestos!$B$8*Supuestos!$B$7)+Supuestos!$B$25*Supuestos!$B$7*(1+Supuestos!$B$26))*$B$8 | E26: =((Acero!$E$42*(Supuestos!$B$6-0.90-0.24)+479.59*Supuestos!$B$8*Supuestos!$B$7)+Supuestos!$B$25*Supuestos!$B$7*(1+Supuestos!$B$26))*$B$8 | F26: Los 23 €/h son de 2024 y no llevan IPC
A27: Gastos fijos de fábrica a precios de 2026 | B27: =Supuestos!$B$28*Supuestos!$B$5/Supuestos!$B$29 | C27: =Supuestos!$B$28*Supuestos!$B$5*Supuestos!$B$30 | D27: =Supuestos!$B$28*Supuestos!$B$5/Supuestos!$B$29 | E27: =Supuestos!$B$28*Supuestos!$B$5/Supuestos!$B$29 | F27: Los 20.430 €/mes son de 2024
A28: Gastos fijos repartidos al ritmo real de la plantilla | B28: =Supuestos!$B$28*(1+Supuestos!$B$5)*(1/$B$20-1/Supuestos!$B$29) | C28: =0 | D28: =Supuestos!$B$28*(1+Supuestos!$B$5)*(1/$B$20-1/Supuestos!$B$29) | E28: =Supuestos!$B$28*(1+Supuestos!$B$5)*(1/$B$20-1/Supuestos!$B$29) | F28: El modelo los reparte entre 2 viviendas al mes
A29: Plantilla parada en el piloto aislado | B29: =0 | C29: =MAX(0,$B$22*(1+$B$8)*Supuestos!$B$30-((Acero!$E$42*(Supuestos!$B$6-0.90-0.24)+479.59*Supuestos!$B$8*Supuestos!$B$7)+Supuestos!$B$25*Supuestos!$B$7*(1+Supuestos!$B$26))*(1+$B$8)) | D29: =0 | E29: =0 | F29: Sin serie, la nómina se paga entera aunque haya pocas horas que cargar
A30: Estructura de RG21 (dirección, comercial, administración, con SS) | B30: =$B$9/$B$20 | C30: =$B$9*Supuestos!$B$30 | D30: =$B$9/$B$20 | E30: =$B$9/$B$20 | F30: No está en el modelo
A31: Garantía y posventa | B31: =('Resumen piloto'!$B$13+SUM(B26:B30))*$B$10 | C31: =('Resumen piloto'!$C$13+SUM(C26:C30))*$B$10 | D31: =($B$12+SUM(D26:D30))*$B$10 | E31: =($B$13+SUM(E26:E30))*$B$10
A32: Imprevistos | B32: =('Resumen piloto'!$B$13+SUM(B26:B30))*$B$11 | C32: =('Resumen piloto'!$C$13+SUM(C26:C30))*$B$11 | D32: =($B$12+SUM(D26:D30))*$B$11 | E32: =($B$13+SUM(E26:E30))*$B$11
A33: Total de lo que falta | B33: =SUM(B26:B32) | C33: =SUM(C26:C32) | D33: =SUM(D26:D32) | E33: =SUM(E26:E32)
A34: Coste del modelo | B34: ='Resumen piloto'!$B$13 | C34: ='Resumen piloto'!$C$13 | D34: =$B$12 | E34: =$B$13
A35: COSTE COMPLETO | B35: =B33+B34 | C35: =C33+C34 | D35: =D33+D34 | E35: =E33+E34
A36: Precio ofertado a NIDO | B36: =$B$14 | C36: =$B$15 | D36: =$B$16 | E36: =$B$17
A37: Margen según el modelo (% sobre venta) | B37: =1-B34/B36 | C37: =1-C34/C36 | D37: =1-D34/D36 | E37: =1-E34/E36
A38: MARGEN REAL con el precio ofertado (€) | B38: =B36-B35 | C38: =C36-C35 | D38: =D36-D35 | E38: =E36-E35
A39: MARGEN REAL (% sobre venta) | B39: =B38/B36 | C39: =C38/C36 | D39: =D38/D36 | E39: =E38/E36
A41: ESCENARIOS: PRECIO SEGÚN EL MARGEN SOBRE EL COSTE COMPLETO
A42: Margen sobre coste (y sobre venta) | B42: Piloto en serie | C42: Pareada en serie | D42: 16 viviendas (14 + 2) | E42: Margen de las 16 | F42: Frente a la oferta de las 16 (3.355.600 €)
A43: 0 % (precio mínimo: solo coste) | B43: =B35*(1+0) | C43: =D35*(1+0) | D43: =(14*D35+2*E35)*(1+0) | E43: =(14*D35+2*E35)*0 | F43: =D43-3355600
A44: 5 % (4,8 % sobre venta) | B44: =B35*(1+0.05) | C44: =D35*(1+0.05) | D44: =(14*D35+2*E35)*(1+0.05) | E44: =(14*D35+2*E35)*0.05 | F44: =D44-3355600
...
