Workbook

Sheet Resumen
A1: Névola · Mediciones por oficio para pedir ofertas · 16 viviendas
A2: Fuente: BC3 del proyecto de ejecución (julio de 2026), con medición, desglose y descripción completa de cada partida. Importes PEM del proyecto, sin IVA, solo como referencia.
A4: Cap. | B4: Oficio (pestaña) | C4: Partidas | D4: Se piden igual | E4: Las sustituye el módulo | F4: Fuera de la vivienda | G4: PEM del proyecto
A5: C.01 | B5: Actuaciones previas | C5: 5 | D5: 0 | E5: 0 | F5: 5 | G5: ='01 Actuaciones previas'!J10 -> 26049.747
A6: C.02 | B6: Movimiento de tierras | C6: 5 | D6: 0 | E6: 0 | F6: 5 | G6: ='02 Movimiento de tierras'!J10 -> 74690.011
A7: C.03 | B7: Saneamiento enterrado | C7: 18 | D7: 2 | E7: 3 | F7: 13 | G7: ='03 Saneamiento enterrado'!J23 -> 91944.62
A8: C.04 | B8: Cimentación y estructura | C8: 14 | D8: 0 | E8: 4 | F8: 10 | G8: ='04 Cimentación y estructura'!J19 -> 371011.56
A9: C.05 | B9: Cubiertas | C9: 3 | D9: 0 | E9: 3 | F9: 0 | G9: ='05 Cubiertas'!J8 -> 121825.85
A10: C.06 | B10: Albañilería | C10: 12 | D10: 0 | E10: 12 | F10: 0 | G10: ='06 Albañilería'!J17 -> 237331.28
A11: C.07 | B11: Impermeabilización y aislamiento | C11: 15 | D11: 2 | E11: 10 | F11: 3 | G11: ='07 Impermeabilización y aislami'!J20 -> 128361.62
A12: C.08 | B12: Pladur: trasdosados, tabiques y techos | C12: 9 | D12: 8 | E12: 1 | F12: 0 | G12: ='08 Pladur trasdosados, tabiques'!J14 -> 250503.1
A13: C.09 | B13: Alicatados y solados | C13: 12 | D13: 9 | E13: 0 | F13: 3 | G13: ='09 Alicatados y solados'!J17 -> 250268.09
A14: C.10 | B14: Carpintería interior | C14: 4 | D14: 4 | E14: 0 | F14: 0 | G14: ='10 Carpintería interior'!J9 -> 62785.372
A15: C.11 | B15: Carpintería exterior y cerrajería | C15: 20 | D15: 14 | E15: 0 | F15: 6 | G15: ='11 Carpintería exterior y cerra'!J25 -> 258815.76
A16: C.12 | B16: Pintura | C16: 2 | D16: 2 | E16: 0 | F16: 0 | G16: ='12 Pintura'!J7 -> 59969.531
A17: C.13 | B17: Electricidad y telecomunicaciones | C17: 55 | D17: 39 | E17: 0 | F17: 16 | G17: ='13 Electricidad y telecomunicac'!J60 -> 237477.9
A18: C.14 | B18: Fontanería, saneamiento y sanitarios | C18: 38 | D18: 23 | E18: 0 | F18: 15 | G18: ='14 Fontanería, saneamiento y sa'!J43 -> 123201.48
A19: C.15 | B19: Climatización, ACS y ventilación | C19: 30 | D19: 30 | E19: 0 | F19: 0 | G19: ='15 Climatización, ACS y ventila'!J35 -> 299448.12
A20: C.16 | B20: Piscina | C20: 19 | D20: 0 | E20: 0 | F20: 19 | G20: ='16 Piscina'!J24 -> 34929.443
A21: C.17 | B21: Urbanización | C21: 25 | D21: 0 | E21: 0 | F21: 25 | G21: ='17 Urbanización'!J30 -> 192743.34
A22: C.18 | B22: Seguridad y salud | C22: 1 | D22: 0 | E22: 0 | F22: 1 | G22: ='18 Seguridad y salud'!J6 -> 31714.16
A23: C.19 | B23: Control de calidad | C23: 14 | D23: 3 | E23: 0 | F23: 11 | G23: ='19 Control de calidad'!J19 -> 50487.98
A24: C.20 | B24: Gestión de residuos | C24: 8 | D24: 0 | E24: 0 | F24: 8 | G24: ='20 Gestión de residuos'!J13 -> 12112.75
B25: Total proyecto (PEM) | C25: =SUM(C5:C24) -> 309 | G25: =SUM(G5:G24) -> 2915671.7
B27: Acero de los módulos (16 viviendas)
B28: Panel y envolvente de los módulos (16 viviendas)
B30: «Se piden igual»: partidas que se ejecutan como en el proyecto, en fábrica o en obra (carpinterías, instalaciones, acabados, sanitarios…). Son las que hay que pedir a cada oficio.
B31: «Las sustituye el módulo»: estructura, forjados, fábricas, cubierta y aislamientos del proyecto convencional. No se piden: los cubren el acero y el panel de las dos últimas pestañas.
B32: «Fuera de la vivienda»: movimiento de tierras, cimentación, acometidas, piscina, urbanización y gastos de obra. Solo entran en las opciones 2, 3 y 4 de NIDO.
B33: La columna «Desglose» reproduce las líneas de medición del proyecto (tipo, unidades y medidas). La de «Datos clave» resume medidas, colores y marcas sacados del texto; la descripción completa va al lado.

Sheet 01 Actuaciones previas
A1: Névola · Actuaciones previas · 16 viviendas
A2: Capítulo C.01 del proyecto de ejecución (BC3 de julio de 2026). Medición de toda la promoción y su desglose tal como viene en el proyecto. Precios del proyecto (CYPE, PEM, sin IVA), solo como referencia.
A4: Código | B4: Partida | C4: Ud | D4: Total 16 viv. | E4: Media por vivienda | F4: Desglose de la medición (proyecto) | G4: Datos clave (medidas, color, marca) | H4: Descripción completa del proyecto | I4: Precio proyecto | J4: Importe PEM | K4: Alcance en el sistema modular
A5: D01QG110 | B5: DESMONTAJE Y RETIRADA CARTEL PUB. INC CARGA/TRANSP | C5: m² | D5: 20 | E5: =D5/16 -> 1.25 | F5: 1 × 5.00 × 4.00 | H5: DESMONTAJE Y RETIRADA CARTEL PUB. INC CARGA/TRANSPDesmontaje y retirada de cartel publicitario formados por vigas y pilares metálicos, i/anclaje previo, recuperación de material aprovechable, apilado y p.p. de costes indirectos, según NTE/ADD-15 y 16. | I5: 53.41 | J5: =D5*I5 -> 1068.2 | K5: Fuera de la vivienda (promotor o Knubo)
A6: D36BA005 | B6: RETIRADA ARBOL INC DESTOCONADO / TROCEADO / CARGA / TRANS | C6: Ud | D6: 4 | E6: =D6/16 -> 0.25 | F6: 4 | H6: RETIRADA ARBOL INC DESTOCONADO / TROCEADO / CARGA / TRANSCortado y troceado por medio de sierra mecánica y transporte fuera de la obra de tronco de árbol, hasta 30 cms de diametro, medido a un metro de altura sobre la rasante del terreno circundante. | I6: 177.3 | J6: =D6*I6 -> 709.2 | K6: Fuera de la vivienda (promotor o Knubo)
A7: DEF040 | B7: DEMOLICIÓN MOCHETAS INSTALACIONES | C7: m³ | D7: 12.43 | E7: =D7/16 -> 0.776875 | F7: Agua: 16 × 1.20 × 0.38 × 1.00 Electricidad: 9 × 1.00 × 0.38 × 1.50 | H7: DEMOLICIÓN MOCHETAS INSTALACIONESDemolición de muro de fábrica de ladrillo cerámico perforado, con martillo neumático, transporte del material a vertedero, con camión basculante cargado a máquina, canon de vertedero y p.p. de medios auxiliares, considerando tambien la carga. | I7: 40.32 | J7: =D7*I7 -> 501.1776 | K7: Fuera de la vivienda (promotor o Knubo)
A8: DMX050 | B8: DEMOLICIÓN ACERADO | C8: m² | D8: 447.95 | E8: =D8/16 -> 27.996875 | F8: Acera: 1 × 289.00 × 1.55 | H8: DEMOLICIÓN ACERADODemolición de pavimento exterior de baldosas y/o losetas de hormigón incluyendo bordillo y base soporte, con martillo neumático, transporte del material a vertedero, con camión basculante cargado a máquina, canon de vertedero y p.p. de medios auxiliares, considerando tambien la carga. | I8: 7.75 | J8: =D8*I8 -> 3471.6125 | K8: Fuera de la vivienda (promotor o Knubo)
A9: 101 | B9: DESBROCE Y LIMPIEZA DEL TERRENO | C9: m² | D9: 7328.36 | E9: =D9/16 -> 458.0225 | F9: Toda la parcela (incluye P17 y P18): 1 × 7328.36 | H9: DESBROCE Y LIMPIEZA DEL TERRENODesbroce y limpieza superficial del terreno por medios mecánicos, para un espesor medio de 20 cm., incluso carga y transporte de tierras al vertedero, a una distancia menor de 20km., considerando ida y vuelta con camión basculante cargado a máquina, canon de vertedero y p.p. de medios auxilares, considerando también la carga. | I9: 2.77 | J9: =D9*I9 -> 20299.557 | K9: Fuera de la vivienda (promotor o Knubo)
B10: Total del capítulo (PEM del proyecto) | J10: =SUM(J5:J9) -> 26049.747

Sheet 02 Movimiento de tierras
A1: Névola · Movimiento de tierras · 16 viviendas
A2: Capítulo C.02 del proyecto de ejecución (BC3 de julio de 2026). Medición de toda la promoción y su desglose tal como viene en el proyecto. Precios del proyecto (CYPE, PEM, sin IVA), solo como referencia.
A4: Código | B4: Partida | C4: Ud | D4: Total 16 viv. | E4: Media por vivienda | F4: Desglose de la medición (proyecto) | G4: Datos clave (medidas, color, marca) | H4: Descripción completa del proyecto | I4: Precio proyecto | J4: Importe PEM | K4: Alcance en el sistema modular
A5: ADE005 | B5: EXCAVACIÓN SÓTANOS | C5: m³ | D5: 140 | E5: =D5/16 -> 8.75 | F5: Cuarto técnico piscinas: 1 × 40.00 × 3.50 | H5: EXCAVACIÓN SÓTANOSExcavación de sótanos de más de 2 m de profundidad, que en todo su perímetro quedan por debajo de la rasante natural, en suelos de compacidad media, por medios mecánicos,transporte de tierras al vertedero, con camión basculante cargado a máquina, canon de vertedero y p.p. de medios auxiliares, considerando tambien la carga. | I5: 2.36 | J5: =D5*I5 -> 330.4 | K5: Fuera de la vivienda (promotor o Knubo)
A6: ADE010 | B6: EXCAVACIÓN POZOS DE CIMENTACIÓN | C6: m³ | D6: 265.92 | E6: =D6/16 -> 16.62 | F6: Zapatas aisladas (demasía incluida en cota variable) PAREADO 1-2: 1 × 24.65 × 1.15 PAREADO 3-4: 1 × 30.20 × 0.75 AISLADA 5: 1 × 12.75 × 1.55 PAREADO 6-7: 1 × 24.65 × 0.95 PAREADO 8-9: 1 × 30.20 × 1.30 AISLADA 10: 1 × 12.60 × 1.25 PAREADO 11-12: 1 × 24.65 × 1.55 PAREADO 13-14: 1 × 30.20 × 0.95 PAREADO 15-16: 1 × 30.20 × 1.65 | H6: EXCAVACIÓN POZOS DE CIMENTACIÓNExcavación de pozos para cimentaciones hasta una profundidad de 2 m, en suelos de compacidad media, por medios mecánicos,transporte de tierras al vertedero, con camión basculante cargado a máquina, canon de vertedero y p.p. de medios auxiliares, considerando tambien la carga. | I6: 11.1 | J6: =D6*I6 -> 2951.712 | K6: Fuera de la vivienda (promotor o Knubo)
A7: ADE010b | B7: EXCAVACIÓN ZANJAS CIMENTACIÓN | C7: m³ | D7: 194.3 | E7: =D7/16 -> 12.14375 | F7: Vigas de atado PAREADO 1-2: 1 × 17.20 × 0.40 PAREADO 3-4: 1 × 16.30 × 0.40 AISLADA 5: 1 × 9.95 × 0.40 PAREADO 6-7: 1 × 17.20 × 0.40 PAREADO 8-9: 1 × 16.30 × 0.40 AISLADA 10: 1 × 10.15 × 0.40 PAREADO 11-12: 1 × 17.20 × 0.40 PAREADO 13-14: 1 × 16.30 × 0.40 PAREADO 15-16: 1 × 16.30 × 0.40 MUROS BLOQUE H.A. para revestir Vallados a calle Perímetro parcela total: 1 × 289.00 × 0.40 × 0.40 Muros separación pareados VIV 1-VIV 2: 1 × 8.35 × 0.40 × 0.40 VIV 3-VIV 4: 1 × 8.80 × 0.40 × 0.40 VIV 6-VIV 7: 1 × 8.35 × 0.40 × 0.40 VIV 8-VIV 9: 1 × 8.35 × 0.40 × 0.40 VIV 11-VIV 12: 1 × 8.70 × 0.40 × 0.40 VIV 13-VIV 14: 1 × 8.35 × 0.40 × 0.40 VIV 15-VIV 16: 1 × 8.35 × 0.40 × 0.40 MUROS BLOQUE H.A. cara vista Separación entre viviendas VIV 1-VIV 2: 1 × 1.90 × 0.40 × 0.40 VIV 2-VIV 3: 1 × 19.75 × 0.40 × 0.40 VIV 3-VIV 4: 1 × 1.50 × 0.40 × 0.40 VIV 4-VIV 5: 1 × 19.75 × 0.40 × 0.40 VIV 5-VIV 6: 1 × 19.75 × 0.40 × 0.40 VIV 6-VIV 7: 1 × 1.90 × 0.40 × 0.40 VIV 8-VIV 9: 1 × 3.90 × 0.40 × 0.40 VIV 9-VIV 10: 1 × 21.75 × 0.40 × 0.40 VIV 10-VIV 11: 1 × 21.75 × 0.40 × 0.40 VIV 11-VIV 12: 1 × 3.60 × 0.40 × 0.40 VIV 13-VIV 14: 1 × 3.00 × 0.40 × 0.40 VIV 14-VIV 15: 1 × 20.85 × 0.40 × 0.40 VIV 15-VIV 16: 1 × 3.00 × 0.40 × 0.40 VIV 16-PARCELA 17: 1 × 21.10 × 0.40 × 0.40 Separación viviendas-Zona común Contención diferencia de niveles VIV 1-VIV 2: 1 × 30.90 × 0.40 × 0.40 VIV 3-VIV 4: 1 × 28.60 × 0.40 × 0.40 VIV 5: 1 × 15.75 × 0.40 × 0.40 VIV 6-VIV 7: 1 × 28.70 × 0.40 × 0.40 1 × 20.60 × 0.40 × 0.40 VIV 8-VIV 9: 1 × 25.65 × 0.40 × 0.40 VIV 10: 1 × 14.15 × 0.40 × 0.40 VIV 11-VIV 12: 1 × 28.75 × 0.40 × 0.40 VIV 13-VIV 14: 1 × 29.90 × 0.40 × 0.40 1 × 21.00 × 0.40 × 0.40 VIV 15-VIV 16: 1 × 31.50 × 0.40 × 0.40 CASETA APEROS: 1 × 13.45 × 0.40 × 0.40 PERÍMETRO PISCINA: 1 × 71.40 × 0.40 × 0.40 | H7: EXCAVACIÓN ZANJAS CIMENTACIÓNExcavación de zanjas para cimentaciones hasta una profundidad de 2 m, en suelos de compacidad media, por medios mecánicos,transporte de tierras al vertedero, con camión basculante cargado a máquina, canon de vertedero y p.p. de medios auxiliares, considerando tambien la carga. | I7: 9.56 | J7: =D7*I7 -> 1857.508 | K7: Fuera de la vivienda (promotor o Knubo)
A8: ADE010c | B8: EXCAVACIÓN ZANJAS INSTALACIONES | C8: m³ | D8: 233 | E8: =D8/16 -> 14.5625 | F8: Red saneamiento enterrada ZONA COMÚN: 1 × 81.00 × 0.40 × 0.40 VIV 1: 1 × 27.60 × 0.40 × 0.40 VIV 2: 1 × 27.60 × 0.40 × 0.40 VIV 3: 1 × 27.60 × 0.40 × 0.40 VIV 4: 1 × 27.60 × 0.40 × 0.40 VIV 5: 1 × 39.40 × 0.40 × 0.40 VIV 6: 1 × 36.60 × 0.40 × 0.40 VIV 7: 1 × 36.60 × 0.40 × 0.40 VIV 8: 1 × 33.10 × 0.40 × 0.40 VIV 9: 1 × 33.80 × 0.40 × 0.40 VIV 10: 1 × 31.45 × 0.40 × 0.40 VIV 11: 1 × 27.60 × 0.40 × 0.40 VIV 12: 1 × 27.60 × 0.40 × 0.40 VIV 13: 1 × 27.60 × 0.40 × 0.40 VIV 14: 1 × 27.60 × 0.40 × 0.40 VIV 15: 1 × 27.60 × 0.40 × 0.40 VIV 16: 1 × 27.60 × 0.40 × 0.40 Agua ZONA COMÚN: 1 × 110.00 × 0.40 × 0.40 VIVIENDAS: 16 × 24.00 × 0.40 × 0.40 Electricidad ZONA COMÚN: 1 × 255.00 × 0.40 × 0.40 VIVIENDAS: 12 × 6.00 × 0.40 × 0.40 2 × 14.00 × 0.40 × 0.40 2 × 19.50 × 0.40 × 0.40 | H8: EXCAVACIÓN ZANJAS INSTALACIONESExcavación de zanjas para instalaciones hasta una profundidad de 2 m, en suelos de compacidad media, por medios mecánicos,transporte de tierras al vertedero, con camión basculante cargado a máquina, canon de vertedero y p.p. de medios auxiliares, considerando tambien la carga. | I8: 12.01 | J8: =D8*I8 -> 2798.33 | K8: Fuera de la vivienda (promotor o Knubo)
A9: ADR030 | B9: RELLENO Y COMPACTACIÓN | C9: m³ | D9: 7681.48 | E9: =D9/16 -> 480.0925 | F9: Toda la parcela (hmedia=1.15 m): 1 × 6679.55 × 1.15 Incluye relleno bordes cimentación encofrada | H9: RELLENO Y COMPACTACIÓNBase de pavimento realizada mediante relleno a cielo abierto, con tierra de préstamo, y compactación en tongadas sucesivas de 30 cm de espesor máximo con rodillo vibrante de guiado manual, hasta alcanzar una densidad seca no inferior al 98% de la máxima obtenida en el ensayo Proctor Modificado, realizado según UNE 103501. El precio incluye el ensayo de Proctor Modificado. | I9: 8.69 | J9: =D9*I9 -> 66752.061 | K9: Fuera de la vivienda (promotor o Knubo)
B10: Total del capítulo (PEM del proyecto) | J10: =SUM(J5:J9) -> 74690.011

Sheet 03 Saneamiento enterrado
A1: Névola · Saneamiento enterrado · 16 viviendas
A2: Capítulo C.03 del proyecto de ejecución (BC3 de julio de 2026). Medición de toda la promoción y su desglose tal como viene en el proyecto. Precios del proyecto (CYPE, PEM, sin IVA), solo como referencia.
A4: Código | B4: Partida | C4: Ud | D4: Total 16 viv. | E4: Media por vivienda | F4: Desglose de la medición (proyecto) | G4: Datos clave (medidas, color, marca) | H4: Descripción completa del proyecto | I4: Precio proyecto | J4: Importe PEM | K4: Alcance en el sistema modular
A5: UAP011 | B5: ARQUETA DE ARRANQUE | C5: Ud | D5: 33 | E5: =D5/16 -> 2.0625 | F5: AA Pluviales: 16 × 1.00 Fecales: 16 × 1.00 Zona común: 1 × 1.00 | G5: Medidas: 125x125x100cm, 150x150cm | H5: ARQUETA DE ARRANQUEFormación de pozo de registro de elementos prefabricados de hormigón en masa, de 0,90 m de diámetro interior y de 2,1 m de altura útil interior máxima, formado por: solera de 25 cm de espesor de hormigón armado HA-30/B/20/IIb+Qb ligeramente armada con malla electrosoldada ME 20x20 Ø 8-8 B 500 T 6x2,20 UNE-EN 10080; base prefabricada de hormigón en masa, de 125x125x100 cm, con dos orificios de 30 cm de diámetro para conexión de colectores, de 90 cm de diámetro interior, con unión rígida machihembrada con junta de goma, según UNE-EN 1917, resistencia a compresión mayor de 250 kg/cm²; anillo prefabricado de hormigón en masa, con unión rígida machihembrada con junta de goma, según UNE-EN 1917, de 100 cm de diámetro interior y 50 cm de altura, resistencia a compresión mayor de 250 kg/cm²; cono asimétrico prefabricado de hormigón en masa, con unión rígida machihembrada con junta de goma, según UNE-EN 1917, de 100 a 60 cm de diámetro interior y 60 cm de altura, resistencia a compresión mayor de 250 kg/cm² y losa alrededor de la boca del cono de 150x150 cm y 20 cm de espesor de hormigón en masa HM-30/B/20/I+Qb; con cierre de tapa circular con bloqueo y marco de fundición clase D-400 según UNE-EN 124, instalado en calzadas de calles, incluyendo las peatonales, o zonas de aparcamiento para todo tipo de vehículos. Incluso hormigón en masa HM-30/B/20/I+Qb para formación de canal en el fondo del pozo y lubricante para montaje.El precio incluye los equipos y la maquinaria necesarios para el desplazamiento y la disposición en obra de los elementos, así como la excavación y el relleno del trasdós. | I5: 699.92 | J5: =D5*I5 -> 23097.36 | K5: Fuera de la vivienda (promotor o Knubo)
A6: ASB020 | B6: CONEXIÓN ACOMETIDA | C6: Ud | D6: 33 | E6: =D6/16 -> 2.0625 | F6: Pozos Pluviales: 16 × 1.00 Fecales: 16 × 1.00 Zona común: 1 × 1.00 | H6: CONEXIÓN ACOMETIDASuministro y montaje de la conexión de la acometida del edificio a la red general de saneamiento del municipio a través de pozo de registro. Incluso junta flexible para el empalme de la acometida y mortero de cemento, industrial, M-5 para repaso y bruñido en el interior del pozo. | I6: 148.82 | J6: =D6*I6 -> 4911.06 | K6: Fuera de la vivienda (promotor o Knubo)
A7: ASB010b | B7: ACOMETIDA DE SANEAMIENTO (ALBAÑAL) | C7: m | D7: 181.15 | E7: =D7/16 -> 11.321875 | F7: Pluviales VIV 1: 1 × 5.10 VIV 2: 1 × 5.75 VIV 3: 1 × 5.00 VIV 4: 1 × 6.20 VIV 5: 1 × 4.90 VIV 6: 1 × 4.90 VIV 7: 1 × 5.00 VIV 8: 1 × 7.60 VIV 9: 1 × 6.20 VIV 10: 1 × 6.70 VIV 11: 1 × 5.75 VIV 12: 1 × 5.45 VIV 13: 1 × 6.75 VIV 14: 1 × 6.25 VIV 15: 1 × 7.10 VIV 16: 1 × 6.70 Fecales VIV 1: 1 × 3.90 VIV 2: 1 × 5.10 VIV 3: 1 × 3.80 VIV 4: 1 × 5.20 VIV 5: 1 × 3.85 VIV 6: 1 × 4.10 VIV 7: 1 × 3.80 VIV 8: 1 × 6.70 VIV 9: 1 × 6.15 VIV 10: 1 × 5.90 VIV 11: 1 × 4.90 VIV 12: 1 × 4.90 VIV 13: 1 × 5.40 VIV 14: 1 × 5.20 VIV 15: 1 × 5.60 VIV 16: 1 × 5.60 ZONA COMÚN: 1 × 5.70 | H7: ACOMETIDA DE SANEAMIENTO (ALBAÑAL)Suministro y montaje de acometida general de saneamiento, para la evacuación de aguas residuales y/o pluviales a la red general del municipio, con una pendiente mínima del 2%, para la evacuación de aguas residuales y/o pluviales, formada por tubo de PVC corrugado, rigidez anular nominal 8 kN/m², de 250 mm de diámetro exterior, con junta elástica, colocado sobre lecho de arena de 10 cm de espesor, debidamente compactada y nivelada con pisón vibrante de guiado manual, relleno lateral compactando hasta los riñones y posterior relleno con la misma arena hasta 30 cm por encima de la generatriz superior de la tubería, con sus correspondientes juntas y piezas especiales. Incluso lubricante para montaje y hormigón en masa HM-20/P/20/I para la posterior reposición del firme existente. El precio incluye la demolición y el levantado del firme existente, así como la excavación y el relleno. | I7: 82.99 | J7: =D7*I7 -> 15033.638 | K7: Fuera de la vivienda (promotor o Knubo)
A8: 0324SH0502 | B8: VÁLVULA ANTIRRETORNO ACOMETIDA | C8: Ud | D8: 33 | E8: =D8/16 -> 2.0625 | F8: Pluviales: 16 × 1.00 Fecales: 16 × 1.00 Zona común: 1 × 1.00 | H8: VÁLVULA ANTIRRETORNO ACOMETIDASuministro, instalación y montaje de válvula antirretorno de doble clapeta con cierre manual para colector de diámetro igual al de la acometida. Totalmente instalada y funcionado de acuerdo con CTE-HS-5 e instrucciones del fabricante, incluida p.p. de accesorios de conexión adecuados, incluso piezas especiales necesarias, ayudas de albañilería y medios auxiliares necesarios, totalmente terminada.Totalmente instalada, probada su estanqueidad y funcionamiento y en servicio según indicaciones de la D.F., CTE DB-HS, y especificaciones técnicas del fabricante. | I8: 122.38 | J8: =D8*I8 -> 4038.54 | K8: Fuera de la vivienda (promotor o Knubo)
A9: 203b | B9: ARQUETA DE PASO 50x50x60 | C9: Ud | D9: 68 | E9: =D9/16 -> 4.25 | F9: AF01: 16 × 2.00 AP01: 16 × 2.00 Zona común: 1 × 4.00 | G9: Medidas: 50x50x60cm | H9: ARQUETA DE PASO 50x50x60Formación de arqueta de paso, enterrada, registrable, construida con fábrica de ladrillo cerámico macizo, de 1/2 pie de espesor, recibido con mortero de cemento, industrial, M-5, de dimensiones interiores 50x50x60 cm, sobre solera de hormigón en masa HM-30/B/20/I+Qb de 15 cm de espesor, formación de pendiente mínima del 2%, con el mismo tipo de hormigón, enfoscada y bruñida interiormente con mortero de cemento, industrial, con aditivo hidrófugo, M-15 formando aristas y esquinas a media caña, cerrada superiormente con tablero cerámico hueco machihembrado y losa de hormigón HA-30/B/20/IIb+Qb, armada con malla electrosoldada y sellada herméticamente con mortero de cemento. Incluso mortero para sellado de juntas y piezas de PVC cortadas longitudinalmente para formación del canal en el fondo de la arqueta. | I9: 124.39 | J9: =D9*I9 -> 8458.52 | K9: Fuera de la vivienda (promotor o Knubo)
A10: 208 | B10: COLECTOR ENTERRADO PVC 110 mm | C10: m | D10: 124 | E10: =D10/16 -> 7.75 | F10: Fecales: 16 × 2.00 Pluviales: 16 × 2.25 Previsión piscina (fecales): 16 × 3.50 | H10: COLECTOR ENTERRADO PVC 110 mmSuministro y montaje de colector enterrado de red horizontal de saneamiento, con arquetas, con una pendiente mínima del 2%, para la evacuación de aguas residuales y/o pluviales, formado por tubo de PVC liso, serie SN-4, rigidez anular nominal 4 kN/m², de 110 mm de diámetro exterior, pegado mediante adhesivo, colocado sobre lecho de arena de 10 cm de espesor, debidamente compactada y nivelada con pisón vibrante de guiado manual, relleno lateral compactando hasta los riñones y posterior relleno con la misma arena hasta 30 cm por encima de la generatriz superior de la tubería. Incluso líquido limpiador y adhesivo para tubos y accesorios de PVC. | I10: 11.81 | J10: =D10*I10 -> 1464.44 | K10: Fuera de la vivienda (promotor o Knubo)
A11: 209 | B11: COLECTOR ENTERRADO PVC 125 mm | C11: m | D11: 221.3 | E11: =D11/16 -> 13.83125 | F11: Pluviales (general cubiertas): 16 × 8.50 Sumideros zona aparcamiento: 13 × 2.40 1 × 5.35 1 × 11.25 1 × 3.85 Zona común: 1 × 33.65 | H11: COLECTOR ENTERRADO PVC 125 mmSuministro y montaje de colector enterrado de red horizontal de saneamiento, con arquetas, con una pendiente mínima del 2%, para la evacuación de aguas residuales y/o pluviales, formado por tubo de PVC liso, serie SN-4, rigidez anular nominal 4 kN/m², de 125 mm de diámetro exterior, pegado mediante adhesivo, colocado sobre lecho de arena de 10 cm de espesor, debidamente compactada y nivelada con pisón vibrante de guiado manual, relleno lateral compactando hasta los riñones y posterior relleno con la misma arena hasta 30 cm por encima de la generatriz superior de la tubería. Incluso líquido limpiador y adhesivo para tubos y accesorios de PVC. | I11: 13.41 | J11: =D11*I11 -> 2967.633 | K11: Fuera de la vivienda (promotor o Knubo)
A12: 210 | B12: COLECTOR ENTERRADO PVC 160 mm | C12: m | D12: 255.1 | E12: =D12/16 -> 15.94375 | F12: Pluviales VIV 1: 1 × 8.50 VIV 2: 1 × 7.65 VIV 3: 1 × 8.50 VIV 4: 1 × 7.65 VIV 5: 1 × 4.55 VIV 6: 1 × 6.55 VIV 7: 1 × 7.50 VIV 8: 1 × 4.05 VIV 9: 1 × 6.40 VIV 10: 1 × 9.30 VIV 11: 1 × 8.50 VIV 12: 1 × 7.65 VIV 13: 1 × 8.50 VIV 14: 1 × 7.65 VIV 15: 1 × 8.50 VIV 16: 1 × 7.65 Fecales VIV 1: 1 × 4.55 VIV 2: 1 × 4.55 VIV 3: 1 × 4.55 VIV 4: 1 × 4.55 VIV 5: 1 × 9.55 VIV 6: 1 × 13.95 VIV 7: 1 × 12.65 VIV 8: 1 × 9.25 VIV 9: 1 × 11.40 VIV 10: 1 × 3.90 VIV 11: 1 × 4.55 VIV 12: 1 × 4.55 VIV 13: 1 × 4.55 VIV 14: 1 × 4.55 VIV 15: 1 × 4.55 VIV 16: 1 × 4.55 Zona común: 1 × 29.80 | H12: COLECTOR ENTERRADO PVC 160 mmSuministro y montaje de colector enterrado de red horizontal de saneamiento, con arquetas, con una pendiente mínima del 2%, para la evacuación de aguas residuales y/o pluviales, formado por tubo de PVC liso, serie SN-4, rigidez anular nominal 4 kN/m², de 160 mm de diámetro exterior, pegado mediante adhesivo, colocado sobre lecho de arena de 10 cm de espesor, debidamente compactada y nivelada con pisón vibrante de guiado manual, relleno lateral compactando hasta los riñones y posterior relleno con la misma arena hasta 30 cm por encima de la generatriz superior de la tubería. Incluso líquido limpiador y adhesivo para tubos y accesorios de PVC. | I12: 17.16 | J12: =D12*I12 -> 4377.516 | K12: Fuera de la vivienda (promotor o Knubo)
A13: ISS010cc | B13: COLECTOR SUSPENDIDO PVC 52 mm | C13: m | D13: 27.2 | E13: =D13/16 -> 1.7 | F13: Suelo radiante: 16 × 1.70 | H13: COLECTOR SUSPENDIDO PVC 52 mmSuministro e instalación de colector suspendido insonorizado de red horizontal, formado por tubo PVC-U, ABS, ASA y PVC-U con carga mineral de 52 mm de diámetro y 2,8 mm de espesor, unión a presión con junta elástica, con una pendiente mínima del 1,00%, para la evacuación de aguas residuales (a baja y alta temperatura) y/o pluviales en el interior de la estructura de los edificios. Incluso material auxiliar para montaje y sujeción a la obra, accesorios y piezas especiales. | I13: 17.53 | J13: =D13*I13 -> 476.816 | K13: Lo sustituye el módulo: no se pide así
A14: ISS010c | B14: COLECTOR SUSPENDIDO PVC 90 mm | C14: m | D14: 84.8 | E14: =D14/16 -> 5.3 | F14: Pluviales: 16 × 5.30 | H14: COLECTOR SUSPENDIDO PVC 90 mmSuministro e instalación de colector suspendido insonorizado de red horizontal, formado por tubo PVC-U, ABS, ASA y PVC-U con carga mineral de 90 mm de diámetro y 5,1 mm de espesor, unión a presión con junta elástica, con una pendiente mínima del 1,00%, para la evacuación de aguas residuales (a baja y alta temperatura) y/o pluviales en el interior de la estructura de los edificios. Incluso material auxiliar para montaje y sujeción a la obra, accesorios y piezas especiales. | I14: 27.09 | J14: =D14*I14 -> 2297.232 | K14: Lo sustituye el módulo: no se pide así
A15: ISS010cb | B15: COLECTOR SUSPENDIDO PVC 110 mm | C15: m | D15: 408 | E15: =D15/16 -> 25.5 | F15: Fecales Baño 2: 16 × 1.45 Baño principal: 16 × 1.15 Cámara sanitaria (cáviti): 16 × 22.90 | H15: COLECTOR SUSPENDIDO PVC 110 mmSuministro e instalación de colector suspendido insonorizado de red horizontal, formado por tubo PVC-U, ABS, ASA y PVC-U con carga mineral de 110 mm de diámetro y 5,3 mm de espesor, unión a presión con junta elástica, con una pendiente mínima del 1,00%, para la evacuación de aguas residuales (a baja y alta temperatura) y/o pluviales en el interior de la estructura de los edificios. Incluso material auxiliar para montaje y sujeción a la obra, accesorios y piezas especiales. | I15: 30.1 | J15: =D15*I15 -> 12280.8 | K15: Lo sustituye el módulo: no se pide así
A16: ISB010 | B16: BAJANTE RESIDUALES. PVC 110 mm | C16: m | D16: 172 | E16: =D16/16 -> 10.75 | F16: F1-F2: 16 × 2.00 × 3.50 Ventilación cámara sanitaria: 7 × 6.00 × 1.20 1 × 4.00 × 1.20 1 × 4.00 × 1.20 | H16: BAJANTE RESIDUALES. PVC 110 mmBajante interior insonorizada de la red de evacuación de aguas residuales, formada por tubo de PVC-U, ABS, ASA y PVC-U con carga mineral, de 110 mm de diámetro y 5,3 mm de espesor; unión a presión con junta elástica. Incluso material auxiliar para montaje y sujeción a la obra, accesorios y piezas especiales. | I16: 31.02 | J16: =D16*I16 -> 5335.44 | K16: Se pide igual (fábrica u obra)
A17: ISB010b | B17: BAJANTE PLUVIALES. PVC 90 mm | C17: m | D17: 163.2 | E17: =D17/16 -> 10.2 | F17: P1-P2: 16 × 6.50 P3: 16 × 3.50 Caseta aperos: 1 × 3.20 | H17: BAJANTE PLUVIALES. PVC 90 mmBajante interior insonorizada de la red de evacuación de aguas pluviales, formada por tubo de PVC-U, ABS, ASA y PVC-U con carga mineral, de 90 mm de diámetro y 5,1 mm de espesor; unión a presión con junta elástica. Incluso material auxiliar para montaje y sujeción a la obra, accesorios y piezas especiales. | I17: 23.47 | J17: =D17*I17 -> 3830.304 | K17: Se pide igual (fábrica u obra)
A18: 0324SH0204 | B18: CANALETA SUMIDERO PREFABRICADA 25 cm. URBANIZACIÓN | C18: m | D18: 15 | E18: =D18/16 -> 0.9375 | F18: Piscina: 1 × 15.00 | H18: CANALETA SUMIDERO PREFABRICADA 25 cm. URBANIZACIÓNSuministro y montaje de canaleta sumidero sifónica longitudinal de fundición en urbanización, en tramos de 1000 mm de largo, 150 mm de ancho y 170 mm de alto, con rejilla cuadriculada de fundición, en piezas de 1000 mm de longitud, incluso p.p. de conexión a saneamiento con tubería de PVC serie F colocado en parcela recibido con solapes de la lámina impermeabilizante, totalmente enrasado con el pavimento de terminación, instalado y conectado a la red de evacuación, todo ello según especificaciones de proyecto, NTE-ISS, DIT del fabricante, marcado CE y CÓDIGO TÉCNICO DE LA EDIFICACIÓN DB-HS. | I18: 30.24 | J18: =D18*I18 -> 453.6 | K18: Fuera de la vivienda (promotor o Knubo)
A19: 212 | B19: SUMIDERO SIFÓNICO | C19: Ud | D19: 82 | E19: =D19/16 -> 5.125 | F19: Cubierta planta no transitable: 16 × 2.00 Cubierta plana transitable (terrazas): 16 × 2.00 Caseta aperos: 1 × 1.00 Exterior viviendas: 16 × 1.00 Cuarto técnico piscinas: 1 × 1.00 | G19: Medidas: 250x250mm | H19: SUMIDERO SIFÓNICOInstalación de sumidero sifónico de PVC, de salida vertical de 90 mm de diámetro, con rejilla de PVC de 250x250 mm, para recogida de aguas pluviales o de locales húmedos. Incluso accesorios de montaje, piezas especiales y elementos de sujeción. | I19: 21.78 | J19: =D19*I19 -> 1785.96 | K19: Fuera de la vivienda (promotor o Knubo)
A20: HRP060 | B20: REBOSADEROS | C20: Ud | D20: 18 | E20: =D20/16 -> 1.125 | F20: Cubiertas planta primera PAREADO TIPO: 7 × 2.00 AISLADA TIPO 1 (VIVIENDA 5): 1 × 2.00 AISLADA TIPO 2 (VIVIENDA 10): 1 × 2.00 | G20: Medidas: 100x220x58mm · Color: blanco | H20: REBOSADEROSGárgola de hormigón polímero de superficie pulida, de color blanco, de 100x220x58 mm y base rectangular, con goterón, recibida con adhesivo cementoso flexible y sellado de la junta perimetral con masilla de poliuretano, previa aplicación de la imprimación. Incluso nivelación y remate de la impermeabilización en caso necesario. | I20: 10.02 | J20: =D20*I20 -> 180.36 | K20: Fuera de la vivienda (promotor o Knubo)
A21: ISD009 | B21: SUMIDERO SIFÓNICO DUCHA | C21: Ud | D21: 1 | E21: =D21/16 -> 0.0625 | F21: Ducha piscina chapoteo: 1 | G21: Medidas: 100x100mm | H21: SUMIDERO SIFÓNICO DUCHASumidero sifónico de PVC con rejilla de acero inoxidable de 100x100 mm y salidas vertical y horizontal de 50 mm de diámetro, para desagüe de ducha de obra. | I21: 10.41 | J21: =D21*I21 -> 10.41 | K21: Fuera de la vivienda (promotor o Knubo)
A22: IVN110 | B22: REJILLA VENTILACIÓN | C22: Ud | D22: 53 | E22: =D22/16 -> 3.3125 | F22: Ventilación cámara sanitaria PAREADO TIPO: 7 × 6.00 VIVIENDA AISLADA (VIVIENDA 5): 1 × 4.00 VIVIENDA AISLADA (VIVIENDA 10): 1 × 4.00 Caseta aperos: 1 × 1.00 Cuarto técnico piscinas: 1 × 2.00 | G22: Medidas: 15x15cm · Color: con | H22: REJILLA VENTILACIÓNRejilla de ventilación de lamas fijas de aluminio lacado color con 60 micras de espesor mínimo de película seca, de dimensiones 15x15 cm. Incluso tornillos.Incluye: Marcado de los puntos de fijación. Colocación y fijación.Criterio de medición de proyecto: Superficie del hueco a cerrar, medida según documentación gráfica de Proyecto.Criterio de medición de obra: Se medirá, con las dimensiones del hueco, la superficie realmente ejecutada según especificaciones de Proyecto. | I22: 17.83 | J22: =D22*I22 -> 944.99 | K22: Fuera de la vivienda (promotor o Knubo)
B23: Total del capítulo (PEM del proyecto) | J23: =SUM(J5:J22) -> 91944.62

Sheet 04 Cimentación y estructura
A1: Névola · Cimentación y estructura · 16 viviendas
A2: Capítulo C.04 del proyecto de ejecución (BC3 de julio de 2026). Medición de toda la promoción y su desglose tal como viene en el proyecto. Precios del proyecto (CYPE, PEM, sin IVA), solo como referencia.
A4: Código | B4: Partida | C4: Ud | D4: Total 16 viv. | E4: Media por vivienda | F4: Desglose de la medición (proyecto) | G4: Datos clave (medidas, color, marca) | H4: Descripción completa del proyecto | I4: Precio proyecto | J4: Importe PEM | K4: Alcance en el sistema modular
A5: CMP010 | B5: POZO DE CIMENTACIÓN (RELLENO A FIRME) | C5: m³ | D5: 194.83 | E5: =D5/16 -> 12.176875 | F5: ZAPATAS AISLADAS/CIMEN ESCALERAS (demasía 25 %) PAREADO 1-2: 1 × 24.65 × 1.25 × 0.65 PAREADO 3-4: 1 × 30.20 × 1.25 × 0.25 AISLADA 5: 1 × 12.75 × 1.25 × 1.05 PAREADO 6-7: 1 × 24.65 × 1.25 × 0.45 PAREADO 8-9: 1 × 30.20 × 1.25 × 0.80 AISLADA 10: 1 × 12.60 × 1.25 × 0.75 PAREADO 11-12: 1 × 24.65 × 1.25 × 1.05 PAREADO 13-14: 1 × 30.20 × 1.25 × 0.45 PAREADO 15-16: 1 × 30.20 × 1.25 × 1.15 | H5: POZO DE CIMENTACIÓN DE HORMIGÓN CICLÓPEOPozo de cimentación de hormigón HL-150/B/20, fabricado en central y vertido desde camión, en el fondo de la excavación previamente realizada. Incluye: Replanteo. Colocación de toques y/o formación de maestras. Vertido y compactación del hormigón. Coronación y enrase del hormigón.Incluye: Replanteo y trazado de las zapatas y de los pilares u otros elementos estructurales que apoyen en las mismas. Vertido y compactación del hormigón. Colocación de las piedras en el hormigón fresco. Coronación y enrase de cimientos. Curado del hormigón.Criterio de medición de proyecto: Volumen teórico, según documentación gráfica de Proyecto.Criterio de medición de obra: Se medirá el volumen teórico ejecutado según especificaciones de Proyecto, sin incluir los incrementos por excesos de excavación no autorizados. | I5: 70.73 | J5: =D5*I5 -> 13780.326 | K5: Fuera de la vivienda (promotor o Knubo)
A6: 301 | B6: HORMIGÓN DE LIMPIEZA h=10 cm | C6: m² | D6: 1841.22 | E6: =D6/16 -> 115.07625 | F6: VIGAS DE ATADO (demasía 25 %) PAREADO 1-2: 1 × 17.20 × 1.25 PAREADO 3-4: 1 × 16.30 × 1.25 AISLADA 5: 1 × 9.95 × 1.25 PAREADO 6-7: 1 × 17.20 × 1.25 PAREADO 8-9: 1 × 16.30 × 1.25 AISLADA 10: 1 × 10.15 × 1.25 PAREADO 11-12: 1 × 17.20 × 1.25 PAREADO 13-14: 1 × 16.30 × 1.25 × 1.25 PAREADO 15-16: 1 × 16.30 × 1.25 BASE SOLERA CÁVITI PAREADO TIPO: 7 × 150.40 AISLADA TIPO 1 (VIVIENDA 5): 1 × 77.10 AISLADA TIPO 2 (VIVIENDA 10): 1 × 77.95 MUROS BLOQUE H.A. para revestir (demasía 25 %) Vallados a calle Perímetro parcela total: 1 × 289.00 × 0.40 × 1.25 Muros separación pareados VIV 1-VIV 2: 1 × 8.35 × 0.40 × 1.25 VIV 3-VIV 4: 1 × 8.80 × 0.40 × 1.25 VIV 6-VIV 7: 1 × 8.35 × 0.40 × 1.25 VIV 8-VIV 9: 1 × 8.35 × 0.40 × 1.25 VIV 11-VIV 12: 1 × 8.70 × 0.40 × 1.25 VIV 13-VIV 14: 1 × 8.35 × 0.40 × 1.25 VIV 15-VIV 16: 1 × 8.35 × 0.40 × 1.25 MUROS BLOQUE H.A. cara vista (demasía 25 %) Separación entre viviendas VIV 1-VIV 2: 1 × 1.90 × 0.40 × 1.25 VIV 2-VIV 3: 1 × 19.75 × 0.40 × 1.25 VIV 3-VIV 4: 1 × 1.50 × 0.40 × 1.25 VIV 4-VIV 5: 1 × 19.75 × 0.40 × 1.25 VIV 5-VIV 6: 1 × 19.75 × 0.40 × 1.25 VIV 6-VIV 7: 1 × 1.90 × 0.40 × 1.25 VIV 8-VIV 9: 1 × 3.90 × 0.40 × 1.25 VIV 9-VIV 10: 1 × 21.75 × 0.40 × 1.25 VIV 10-VIV 11: 1 × 21.75 × 0.40 × 1.25 VIV 11-VIV 12: 1 × 3.60 × 0.40 × 1.25 VIV 13-VIV 14: 1 × 3.00 × 0.40 × 1.25 VIV 14-VIV 15: 1 × 20.85 × 0.40 × 1.25 VIV 15-VIV 16: 1 × 3.00 × 0.40 × 1.25 VIV 16-PARCELA 17: 1 × 21.10 × 0.40 × 1.25 Separación viviendas-Zona común (demasía 25 %) Contención diferencia de niveles VIV 1-VIV 2: 1 × 30.90 × 0.40 × 1.25 VIV 3-VIV 4: 1 × 28.60 × 0.40 × 1.25 VIV 5: 1 × 15.75 × 0.40 × 1.25 VIV 6-VIV 7: 1 × 28.70 × 0.40 × 1.25 1 × 20.60 × 0.40 × 1.25 VIV 8-VIV 9: 1 × 25.65 × 0.40 × 1.25 VIV 10: 1 × 14.15 × 0.40 × 1.25 VIV 11-VIV 12: 1 × 28.75 × 0.40 × 1.25 VIV 13-VIV 14: 1 × 29.90 × 0.40 × 1.25 1 × 21.00 × 0.40 × 1.25 VIV 15-VIV 16: 1 × 31.50 × 0.40 × 1.25 CASETA APEROS: 1 × 13.45 × 0.40 × 1.25 PERÍMETRO PISCINA: 1 × 71.40 × 0.40 × 1.25 CUARTO TÉCNICO PISCINA: 1 × 21.00 | H6: HORMIGÓN DE LIMPIEZA h=10 cmCapa de hormigón de limpieza y nivelado de fondos de cimentación, de 10 cm de espesor, de hormigón HL-150/B/20, fabricado en central y vertido desde camión, en el fondo de la excavación previamente realizada. Incluye: Replanteo. Colocación de toques y/o formación de maestras. Vertido y compactación del hormigón. Coronación y enrase del hormigón. | I6: 7.31 | J6: =D6*I6 -> 13459.318 | K6: Fuera de la vivienda (promotor o Knubo)
A7: CSZ020 | B7: ENCOFRADO CIMENTACIÓN | C7: m² | D7: 771 | E7: =D7/16 -> 48.1875 | F7: ZAPATAS AISLADAS/CIMEN ESCALERAS/VIGAS DE ATADO PAREADO 1-2: 1 × 155.70 × 0.60 PAREADO 3-4: 1 × 159.80 × 0.60 AISLADA 5: 1 × 88.80 × 0.60 PAREADO 6-7: 1 × 155.70 × 0.60 PAREADO 8-9: 1 × 159.80 × 0.60 AISLADA 10: 1 × 89.90 × 0.60 PAREADO 11-12: 1 × 155.70 × 0.60 PAREADO 13-14: 1 × 159.80 × 0.60 PAREADO 15-16: 1 × 159.80 × 0.60 | H7: ENCOFRADO CIMENTACIÓNMontaje de sistema de encofrado recuperable de madera, para zapata de cimentación, formado por tablones de madera, amortizables en 10 usos, y posterior desmontaje del sistema de encofrado. Incluso elementos de sustentación, fijación y acodalamientos necesarios para su estabilidad y líquido desencofrante para evitar la adherencia del hormigón al encofrado. | I7: 13.83 | J7: =D7*I7 -> 10662.93 | K7: Fuera de la vivienda (promotor o Knubo)
A8: CSZ030 | B8: ZAPATA HORMIGÓN ARMADO HA-25/F/20/XC2 | C8: m³ | D8: 110.07 | E8: =D8/16 -> 6.879375 | F8: ZAPATAS AISLADAS/CIMEN ESCALERAS PAREADO 1-2: 1 × 24.65 × 0.50 PAREADO 3-4: 1 × 30.20 × 0.50 AISLADA 5: 1 × 12.75 × 0.50 PAREADO 6-7: 1 × 24.65 × 0.50 PAREADO 8-9: 1 × 30.20 × 0.50 AISLADA 10: 1 × 12.60 × 0.50 PAREADO 11-12: 1 × 24.65 × 0.50 PAREADO 13-14: 1 × 30.20 × 0.50 PAREADO 15-16: 1 × 30.20 × 0.50 | H8: ZAPATA HORMIGÓN ARMADO HA-25/F/20/XC2Zapata de cimentación de hormigón armado, realizada con hormigón HA-25/F/20/XC2 fabricado en central, y vertido con cubilote, y acero, UNE-EN 10080 B 500 S, con una cuantía aproximada de 35,1 kg/m³. Incluso armaduras de espera del pilar, alambre de atar y separadores.Criterio de valoración económica: El precio incluye la elaboración de la ferralla (corte, doblado y conformado de elementos) en taller industrial y el montaje en el lugar definitivo de su colocación en obra, pero no incluye el encofrado.Incluye: Replanteo y trazado de las zapatas y de los pilares u otros elementos estructurales que apoyen en las mismas. Colocación de separadores y fijación de las armaduras. Vertido y compactación del hormigón. Coronación y enrase de cimientos. Curado del hormigón.Criterio de medición de proyecto: Volumen medido sobre las secciones teóricas de la excavación, según documentación gráfica de Proyecto.Criterio de medición de obra: Se medirá el volumen teórico ejecutado según especificaciones de Proyecto, sin incluir los incrementos por excesos de excavación no autorizados. | I8: 142.04 | J8: =D8*I8 -> 15634.343 | K8: Fuera de la vivienda (promotor o Knubo)
A9: CAV030 | B9: VIGA DE ATADO HA-25/F/20/XC2 | C9: m³ | D9: 54.76 | E9: =D9/16 -> 3.4225 | F9: VIGAS DE ATADO PAREADO 1-2: 1 × 17.20 × 0.40 PAREADO 3-4: 1 × 16.30 × 0.40 AISLADA 5: 1 × 9.95 × 0.40 PAREADO 6-7: 1 × 17.20 × 0.40 PAREADO 8-9: 1 × 16.30 × 0.40 AISLADA 10: 1 × 10.15 × 0.40 PAREADO 11-12: 1 × 17.20 × 0.40 PAREADO 13-14: 1 × 16.30 × 0.40 PAREADO 15-16: 1 × 16.30 × 0.40 | H9: VIGA DE ATADO HA-25/F/20/XC2/VALLADOSViga de atado de hormigón armado, realizada con hormigón HA-25/F/20/XC2 fabricado en central, y vertido con cubilote, y acero, UNE-EN 10080 B 500 S, con una cuantía aproximada de 61,8 kg/m³. Incluso alambre de atar y separadores.Criterio de valoración económica: El precio incluye la elaboración de la ferralla (corte, doblado y conformado de elementos) en taller industrial y el montaje en el lugar definitivo de su colocación en obra, pero no incluye el encofrado.Incluye: Colocación de la armadura con separadores homologados. Vertido y compactación del hormigón. Coronación y enrase. Curado del hormigón.Criterio de medición de proyecto: Volumen medido sobre las secciones teóricas de la excavación, según documentación gráfica de Proyecto.Criterio de medición de obra: Se medirá el volumen teórico ejecutado según especificaciones de Proyecto, sin incluir los incrementos por excesos de excavación no autorizados. | I9: 178.34 | J9: =D9*I9 -> 9765.8984 | K9: Fuera de la vivienda (promotor o Knubo)
A10: CAV030b | B10: ZUNCHO HA-25/F/20/XC2/VALLADOS | C10: m³ | D10: 139.54 | E10: =D10/16 -> 8.72125 | F10: MUROS BLOQUE H.A. para revestir Vallados a calle Perímetro parcela total: 1 × 289.00 × 0.40 × 0.40 Muros separación pareados VIV 1-VIV 2: 1 × 8.35 × 0.40 × 0.40 VIV 3-VIV 4: 1 × 8.80 × 0.40 × 0.40 VIV 6-VIV 7: 1 × 8.35 × 0.40 × 0.40 VIV 8-VIV 9: 1 × 8.35 × 0.40 × 0.40 VIV 11-VIV 12: 1 × 8.70 × 0.40 × 0.40 VIV 13-VIV 14: 1 × 8.35 × 0.40 × 0.40 VIV 15-VIV 16: 1 × 8.35 × 0.40 × 0.40 MUROS BLOQUE H.A. cara vista Separación entre viviendas VIV 1-VIV 2: 1 × 1.90 × 0.40 × 0.40 VIV 2-VIV 3: 1 × 19.75 × 0.40 × 0.40 VIV 3-VIV 4: 1 × 1.50 × 0.40 × 0.40 VIV 4-VIV 5: 1 × 19.75 × 0.40 × 0.40 VIV 5-VIV 6: 1 × 19.75 × 0.40 × 0.40 VIV 6-VIV 7: 1 × 1.90 × 0.40 × 0.40 VIV 8-VIV 9: 1 × 3.90 × 0.40 × 0.40 VIV 9-VIV 10: 1 × 21.75 × 0.40 × 0.40 VIV 10-VIV 11: 1 × 21.75 × 0.40 × 0.40 VIV 11-VIV 12: 1 × 3.60 × 0.40 × 0.40 VIV 13-VIV 14: 1 × 3.00 × 0.40 × 0.40 VIV 14-VIV 15: 1 × 20.85 × 0.40 × 0.40 VIV 15-VIV 16: 1 × 3.00 × 0.40 × 0.40 VIV 16-PARCELA 17: 1 × 21.10 × 0.40 × 0.40 Separación viviendas-Zona común Contención diferencia de niveles VIV 1-VIV 2: 1 × 30.90 × 0.40 × 0.40 VIV 3-VIV 4: 1 × 28.60 × 0.40 × 0.40 VIV 5: 1 × 15.75 × 0.40 × 0.40 VIV 6-VIV 7: 1 × 28.70 × 0.40 × 0.40 1 × 20.60 × 0.40 × 0.40 VIV 8-VIV 9: 1 × 25.65 × 0.40 × 0.40 VIV 10: 1 × 14.15 × 0.40 × 0.40 VIV 11-VIV 12: 1 × 28.75 × 0.40 × 0.40 VIV 13-VIV 14: 1 × 29.90 × 0.40 × 0.40 1 × 21.00 × 0.40 × 0.40 VIV 15-VIV 16: 1 × 31.50 × 0.40 × 0.40 CASETA APEROS: 1 × 13.45 × 0.40 × 0.40 PERÍMETRO PISCINA: 1 × 71.40 × 0.40 × 0.40 | H10: ZUNCHO HA-25/F/20/XC2/VALLADOSZuncho de hormigón armado, realizada con hormigón HA-25/F/20/XC2 fabricado en central, y vertido con cubilote, y acero, UNE-EN 10080 B 500 S, con una cuantía aproximada de 61,8 kg/m³. Incluso alambre de atar y separadores.Criterio de valoración económica: El precio incluye la elaboración de la ferralla (corte, doblado y conformado de elementos) en taller industrial y el montaje en el lugar definitivo de su colocación en obra, pero no incluye el encofrado.Incluye: Colocación de la armadura con separadores homologados. Vertido y compactación del hormigón. Coronación y enrase. Curado del hormigón.Criterio de medición de proyecto: Volumen medido sobre las secciones teóricas de la excavación, según documentación gráfica de Proyecto.Criterio de medición de obra: Se medirá el volumen teórico ejecutado según especificaciones de Proyecto, sin incluir los incrementos por excesos de excavación no autorizados. | I10: 178.34 | J10: =D10*I10 -> 24885.564 | K10: Fuera de la vivienda (promotor o Knubo)
A11: ANS030 | B11: SOLERA VENTILADA C-50 "CÁVITI" 50+5 cm | C11: m² | D11: 1207.85 | E11: =D11/16 -> 75.490625 | F11: PAREADO TIPO: 7 × 150.40 AISLADA TIPO 1 (VIVIENDA 5): 1 × 77.10 AISLADA TIPO 2 (VIVIENDA 10): 1 × 77.95 | G11: Medidas: 750x580x500mm · Color: negro · Marca/serie: CÁVITI | H11: SOLERA VENTILADA C-50 "CÁVITI" 50+5 cmSolera ventilada de hormigón armado de 50+5 cm de canto, sobre encofrado perdido de piezas de polipropileno reciclado, C-50 "CÁVITI", de 750x580x500 mm, color negro, realizada con hormigón HA-25/B/12/IIa fabricado en central, y vertido con cubilote, y malla electrosoldada ME 10x10 Ø 5-5 B 500 T 6x2,20 UNE-EN 10080 como armadura de reparto, colocada sobre separadores homologados en capa de compresión de 5 cm de espesor, incluida tabica perimetral de hormigón armado de ancho máximo 15 cm y encofrado de la misma; con juntas de retracción de 5 mm de espesor, mediante corte con disco de diamante; apoyado todo ello sobre base de hormigón de limpieza (NO INCLUIDO EN ESTE PRECIO). Incluso panel de poliestireno expandido de 3 cm de espesor, para la ejecución de juntas de dilatación. | I11: 39.45 | J11: =D11*I11 -> 47649.683 | K11: Lo sustituye el módulo: no se pide así
A12: EHU030b | B12: FORJADO UNIDIRECCIONAL 30 cm SEMIVIGUETA ARMADA/BOV HORMIGÓN/PILARES Y VIGAS 0,134 m³/m² | C12: m² | D12: 1285.15 | E12: =D12/16 -> 80.321875 | F12: PRIMER FORJADO (Techo de planta baja) PAREADO TIPO: 7 × 160.60 AISLADA TIPO 1 (VIVIENDA 5): 1 × 81.55 AISLADA TIPO 2 (VIVIENDA 10): 1 × 79.40 | H12: FORJADO UNIDIRECCIONAL 30 cm SEMIVIGUETA ARMADA/BOV HORMIGÓN/PILARES Y VIGAS 0,134 m³/m²Estructura de hormigón armado, realizada con hormigón HA-25/F/20/X0 fabricado en central, y vertido con cubilote, con un volumen total de hormigón en forjado y vigas de 0,134 m³/m², y acero, UNE-EN 10080 B 500 S, en zona de paños, vigas y zunchos, cuantía 6,4 kg/m², constituida por: FORJADO UNIDIRECCIONAL: horizontal, de canto 30 cm, intereje de 72 cm; montaje y desmontaje de sistema de encofrado continuo, con acabado tipo industrial para revestir, formado por: superficie encofrante de tableros de madera tratada, reforzados con varillas y perfiles, amortizables en 25 usos, estructura soporte horizontal de sopandas metálicas y accesorios de montaje, amortizables en 150 usos y estructura soporte vertical de puntales metálicos, amortizables en 150 usos; semivigueta armada con zapatilla de hormigón forjado unidireccional; bovedilla de hormigón; capa de compresión de 5 cm de espesor, con armadura de reparto formada por malla electrosoldada ME 20x20 Ø 5-5 B 500 T 6x2,20 UNE-EN 10080; vigas planas/descuelgue; altura libre de planta de entre 3 y 4 m. Incluye pilares de sección rectangular o cuadrada de hormigón armado, realizado con hormigón HA-25/F/20/XC1 fabricado en central, y vertido con cubilote, y acero, UNE-EN 10080 B 500 S, con una cuantía aproximada de 125,1 kg/m³, alambre de atar y separadores. Incluso agente filmógeno, para el curado de hormigones y morteros.Criterio de valoración económica: El precio incluye la elaboración de la ferralla (corte, doblado y conformado de elementos) en taller industrial y el montaje en el lugar definitivo de su colocación en obra.Incluye: Replanteo del sistema de encofrado. Montaje del sistema de encofrado. Replanteo de la geometría de la planta sobre el encofrado. Colocación de viguetas y bovedillas. Colocación de las armaduras con separadores homologados. Vertido y compactación del hormigón. Regleado y nivelación de la capa de compresión. Curado del hormigón. Desmontaje del sistema de encofrado.Criterio de medición de proyecto: Superficie medida en verdadera magnitud desde las caras exteriores de los zunchos del perímetro, según documentación gráfica de Proyecto, deduciendo los huecos de superficie mayor de 6 m².Criterio de medición de obra: Se medirá, en verdadera magnitud, desde las caras exteriores de los zunchos del perímetro, la superficie realmente ejecutada según especificaciones de Proyecto, deduciendo los huecos de superficie mayor de 6 m². Se consideran incluidos todos los elementos integrantes de la estructura señalados en los planos y detalles del Proyecto. | I12: 83.78 | J12: =D12*I12 -> 107669.87 | K12: Lo sustituye el módulo: no se pide así
A13: EHU030 | B13: FORJADO UNIDIRECCIONAL 30 cm SEMIVIGUETA ARMADA/BOV HORMIGÓN/PILARES Y VIGAS 0,147 m³/m² | C13: m² | D13: 1091.6 | E13: =D13/16 -> 68.225 | F13: SEGUNDO FORJADO (Techo de planta primera) PAREADO TIPO: 7 × 135.40 AISLADA TIPO 1 (VIVIENDA 5): 1 × 72.50 AISLADA TIPO 2 (VIVIENDA 10): 1 × 71.30 | H13: FORJADO UNIDIRECCIONAL 30 cm SEMIVIGUETA ARMADA/BOV HORMIGÓN/PILARES Y VIGAS 0,147 m³/m²Estructura de hormigón armado, realizada con hormigón HA-25/F/20/X0 fabricado en central, y vertido con cubilote, con un volumen total de hormigón en forjado y vigas de 0,147 m³/m², y acero, UNE-EN 10080 B 500 S, en zona de paños, vigas y zunchos, cuantía 6,9 kg/m², constituida por: FORJADO UNIDIRECCIONAL: horizontal, de canto 30 cm, intereje de 72 cm; montaje y desmontaje de sistema de encofrado continuo, con acabado tipo industrial para revestir, formado por: superficie encofrante de tableros de madera tratada, reforzados con varillas y perfiles, amortizables en 25 usos, estructura soporte horizontal de sopandas metálicas y accesorios de montaje, amortizables en 150 usos y estructura soporte vertical de puntales metálicos, amortizables en 150 usos; semivigueta armada con zapatilla de hormigón forjado unidireccional; bovedilla de hormigón; capa de compresión de 5 cm de espesor, con armadura de reparto formada por malla electrosoldada ME 20x20 Ø 5-5 B 500 T 6x2,20 UNE-EN 10080; vigas planas/descuelgue; altura libre de planta de entre 3 y 4 m. Incluye pilares de sección rectangular o cuadrada de hormigón armado, realizado con hormigón HA-25/F/20/XC1 fabricado en central, y vertido con cubilote, y acero, UNE-EN 10080 B 500 S, con una cuantía aproximada de 125,1 kg/m³, alambre de atar y separadores. Incluso agente filmógeno, para el curado de hormigones y morteros.Criterio de valoración económica: El precio incluye la elaboración de la ferralla (corte, doblado y conformado de elementos) en taller industrial y el montaje en el lugar definitivo de su colocación en obra.Incluye: Replanteo del sistema de encofrado. Montaje del sistema de encofrado. Replanteo de la geometría de la planta sobre el encofrado. Colocación de viguetas y bovedillas. Colocación de las armaduras con separadores homologados. Vertido y compactación del hormigón. Regleado y nivelación de la capa de compresión. Curado del hormigón. Desmontaje del sistema de encofrado.Criterio de medición de proyecto: Superficie medida en verdadera magnitud desde las caras exteriores de los zunchos del perímetro, según documentación gráfica de Proyecto, deduciendo los huecos de superficie mayor de 6 m².Criterio de medición de obra: Se medirá, en verdadera magnitud, desde las caras exteriores de los zunchos del perímetro, la superficie realmente ejecutada según especificaciones de Proyecto, deduciendo los huecos de superficie mayor de 6 m². Se consideran incluidos todos los elementos integrantes de la estructura señalados en los planos y detalles del Proyecto. | I13: 85.14 | J13: =D13*I13 -> 92938.824 | K13: Lo sustituye el módulo: no se pide así
A14: EHE010 | B14: LOSA DE ESCALERA h=17 cm | C14: m² | D14: 112 | E14: =D14/16 -> 7 | F14: TODA LA OBRA: 16 × 7.00 × 1.00 | H14: LOSA DE ESCALERA h=17 cmLosa de escalera de hormigón armado de 17 cm de espesor, con peldañeado de fábrica (no incluido en este precio), realizada con hormigón HA-25/F/20/XC2 fabricado en central, y vertido con cubilote, y acero UNE-EN 10080 B 500 S, con una cuantía aproximada de 20,5 kg/m²; montaje y desmontaje de sistema de encofrado, con acabado tipo industrial para revestir en su cara inferior y laterales, en planta de hasta 3 m de altura libre, formado por: superficie encofrante de tablones de madera de pino, amortizables en 10 usos, estructura soporte horizontal de tablones de madera de pino, amortizables en 10 usos y estructura soporte vertical de puntales metálicos, amortizables en 150 usos. Incluso alambre de atar, separadores y líquido desencofrante, para evitar la adherencia del hormigón al encofrado. | I14: 69.16 | J14: =D14*I14 -> 7745.92 | K14: Lo sustituye el módulo: no se pide así
A15: CSL010 | B15: LOSA CIMENTACIÓN C. TÉCNICO PISCINAS | C15: m³ | D15: 21 | E15: =D15/16 -> 1.3125 | F15: Base cuarto técnico piscinas: 1 × 21.00 | H15: LOSA CIMENTACIÓN C. TÉCNICO PISCINASLosa de cimentación de hormigón armado, realizada con hormigón HA-25/F/20/XC2 fabricado en central, y vertido con bomba, y acero UNE-EN 10080 B 500 S, con una cuantía aproximada de 85 kg/m³; acabado superficial liso mediante regla vibrante. Incluso armaduras para formación de foso de ascensor, refuerzos, pliegues, encuentros, arranques y esperas en muros, escaleras y rampas, cambios de nivel, alambre de atar, y separadores. | I15: 131.67 | J15: =D15*I15 -> 2765.07 | K15: Fuera de la vivienda (promotor o Knubo)
A16: EHL010 | B16: LOSA h= 20 cm CASETA APEROS/C TÉCNICO PISCINAS | C16: m² | D16: 34.45 | E16: =D16/16 -> 2.153125 | F16: Forjado caseta aperos: 1 × 13.45 Forjado cuarto técnico piscinas: 1 × 21.00 | H16: LOSA h= 20 cm CASETA APEROS/C TÉCNICO PISCINASLosa maciza de hormigón armado, horizontal, con altura libre de planta de hasta 3 m, canto 20 cm, realizada con hormigón HA-25/B/20/IIa fabricado en central, y vertido con cubilote, y acero UNE-EN 10080 B 500 S, con una cuantía aproximada de 25 kg/m²; montaje y desmontaje de sistema de encofrado continuo, con acabado tipo industrial para revestir, formado por: superficie encofrante de tableros de madera tratada, reforzados con varillas y perfiles, amortizables en 25 usos; estructura soporte horizontal de sopandas metálicas y accesorios de montaje, amortizables en 150 usos y estructura soporte vertical de puntales metálicos, amortizables en 150 usos. Incluso nervios y zunchos perimetrales de planta y huecos, alambre de atar, separadores, aplicación de líquido desencofrante y agente filmógeno para el curado de hormigones y morteros. | I16: 136.99 | J16: =D16*I16 -> 4719.3055 | K16: Fuera de la vivienda (promotor o Knubo)
A17: CCS030b | B17: MURO SÓTANO HORMIGÓN ARMADO/2C 25cm HA-25/F/20/XC2 | C17: m³ | D17: 12.95 | E17: =D17/16 -> 0.809375 | F17: Perímetro cuarto técnico piscinas: 1 × 18.50 × 0.25 × 2.80 | H17: MURO SÓTANO HORMIGÓN ARMADO/2C 25cm HA-25/F/20/XC2Muro de sótano de hormigón armado encofrado a 2 caras, realizado con hormigón HA-25/F/20/XC2 fabricado en central, y vertido con bomba, y acero UNE-EN 10080 B 500 S, con una cuantía aproximada de 77,8 kg/m³(incluyendo armadura de pilares a cimentación), ejecutado por bataches, con un grado de complejidad medio, montaje y desmontaje de sistema de encofrado con acabado tipo industrial para revestir, realizado con paneles metálicos modulares, amortizables en 150 usos. Incluso alambre de atar, separadores, pasamuros para paso de los tensores y líquido desencofrante para evitar la adherencia del hormigón al encofrado. Incluso alambre de atar y separadores; cordón de polietileno expandido, para fondo de junta; masilla elastómera tixotrópica, monocomponente, aplicada con pistola desde el fondo de junta hacia fuera; y posterior revestimiento con mortero tixotrópico monocomponente, para sellado impermeabilizante de los huecos pasamuros para paso de los tensores del encofrado.Criterio de valoración económica: El precio incluye la elaboración y el montaje de la ferralla en el lugar definitivo de su colocación en obra, así como el encofrado.Incluye: Colocación de la armadura con separadores homologados. Resolución de juntas de construcción. Limpieza de la base de apoyo del muro en la cimentación. Vertido y compactación del hormigón. Curado del hormigón. Extracción de los pasamuros. Sellado de los huecos pasamuros. Reparación de defectos superficiales, si procede.Criterio de medición de proyecto: Volumen medido sobre la sección teórica de cálculo, según documentación gráfica de Proyecto, deduciendo los huecos de superficie mayor de 2 m².Criterio de medición de obra: Se medirá el volumen teórico ejecutado según especificaciones de Proyecto, deduciendo los huecos de superficie mayor de 2 m².Criterio de valoración económica: El precio incluye la elaboración y el montaje de la ferralla en el lugar definitivo de su colocación en obra, incluyendo armado de pilares y el encofrado. | I17: 334.8 | J17: =D17*I17 -> 4335.66 | K17: Fuera de la vivienda (promotor o Knubo)
A18: D04PS155 | B18: SOLERA HA-25 2#200x200x5 20 cm+ENCACHADO+PVC | C18: m² | D18: 559.45 | E18: =D18/16 -> 34.965625 | F18: PORCHE JARDÍN (pérgola posterior) PAREADO TIPO: 14 × 23.55 AISLADA TIPO 1 (VIVIENDA 5): 1 × 24.70 AISLADA TIPO 2 (VIVIENDA 10): 1 × 22.55 ZONA COMÚN Piscina adultos: 1 × 142.25 Piscina chapoteo: 1 × 40.25 | G18: Medidas: 200x200x5mm | H18: SOLERA HA-25 2#200x200x5 20 cm+ENCACHADO+PVCSolera de 20 cm de espesor, realizada con hormigón HA-25/F/20/XC2 N/mm², tamaño máximo del árido 20 mm elaborado en central, i/vertido, colocación y armado con doble mallazo electrosoldado #200x200x5 mm, incluso p.p. de juntas, aserrado de las mismas, fratasado y encachado de piedra caliza 40/80 de 20 cm de espesor, extendido y compactado con pisón, con lámina intermedia de PVC Danopol HS de 1,5 mm. Según Codigo Estructural. | I18: 26.81 | J18: =D18*I18 -> 14998.854 | K18: Fuera de la vivienda (promotor o Knubo)
B19: Total del capítulo (PEM del proyecto) | J19: =SUM(J5:J18) -> 371011.56

Sheet 05 Cubiertas
A1: Névola · Cubiertas · 16 viviendas
A2: Capítulo C.05 del proyecto de ejecución (BC3 de julio de 2026). Medición de toda la promoción y su desglose tal como viene en el proyecto. Precios del proyecto (CYPE, PEM, sin IVA), solo como referencia.
A4: Código | B4: Partida | C4: Ud | D4: Total 16 viv. | E4: Media por vivienda | F4: Desglose de la medición (proyecto) | G4: Datos clave (medidas, color, marca) | H4: Descripción completa del proyecto | I4: Precio proyecto | J4: Importe PEM | K4: Alcance en el sistema modular
A5: D08PD002 | B5: CUBIERTA PLANA NO TRANSITABLE/GRAVA | C5: m² | D5: 1195.45 | E5: =D5/16 -> 74.715625 | F5: CUBIERTAS PAREADOS: 7 × 147.50 AISLADA TIPO 1 (VIVIENDA 5): 1 × 76.35 AISLADA TIPO 2 (VIVIENDA 10): 1 × 75.40 CASETA APEROS: 1 × 11.20 | G5: Medidas: 1250x600mm | H5: CUBIERTA PLANA NO TRANSITABLE/GRAVACubierta invertida no transitable no ventilada acabada en grava u hormigon regleado, para zonas climáticas D/E, constituida por:1) Barrera de vapor encima de forjado con lámina de LDPE (film de polietileno baja densidad), VAPOR FLAG de SOPREMA2) Capa de hormigón celular de 8 cm de espesor medio, para formación de pendientes (mínima 2%), con tendido de regularización con mortero de cemento M5 de 2 cm de espesor. 3) Membrana impermeabilizante bicapa ADHERIDA al soporte formada por emulsión asfáltica EMUFAL PRIMER con una dotación > 300 g/m², LBM plastomérico APP con armadura de fieltro de fibra de vidrio (FV) con una flexibilidad a bajas tª = -15ºC tipo MORTERPLAS FV 3 kg designación: LBM-30-FV según UNE 104410:2013, lámina superior totalmente adherida a la inferior lámina de betún modificado plastomérico APP con armadura de fieltro de fibra de poliester (FP) con una flexibilidad a bajas tª = -15ºC tipo SOPRALENE ELITE FP 4 kg designación: LBM-40 FP según UNE 104410:2013. 4) Capa separadora de geotextil no tejido de alta tenacidad a base de polipropileno termosoldado con resistencia a la tracción de 6,5 kN/m y de resistencia al punzonamiento estático (CBR) de 1100 N con un gramage de 90 g/m² TEXXAM 700. 5) Capa de aislamiento térmico formada por planchas de poliestireno extruido de dimensiones 1250x600 mm con juntas a media madera de resistencia a la compresión de 300 KPa, conductividad térmica Lambda 0,036 W/mºK y de espesor 100 mm tipo XPS SL 100 instalada encajando las juntas a media madera para evitar puentes térmicos. Cumple para las zonas climáticas D/E. (NO INCLUIDO EN ESTE PRECIO) 6) Capa separadora antipunzonante de geotextil no tejido de alta tenacidad a base de polipropileno termosoldado con resistencia a la tracción de 12,5 kN/m y de resistencia al punzonamiento estático (CBR) de 2250 N con un gramaje de 150 g/m² TEXXAM 1500.7) Capa de gravilla de canto rodado de 6 cm de espesor. | I5: 88.8 | J5: =D5*I5 -> 106155.96 | K5: Lo sustituye el módulo: no se pide así
