Workbook

Sheet Resumen
A1: NÉVOLA (Guadalix de la Sierra): 16 chalets en sistema modular. Estimación de precio
A2: Promotor: Nido Capital. Base: dossier comercial del 22/07/2025 (planos de presentación y memoria de calidades orientativa). Precios: banco de precios Tini/DWHAI 2024, actualizado.
A4: Capítulo | B4: Pareada | C4: Independiente | D4: €/m² pareada | E4: % del total
A5: 01 ESTRUCTURA METÁLICA DE MÓDULOS | B5: ='Presupuesto vivienda'!J6 | C5: ='Presupuesto vivienda'!K6 | D5: =B5/Supuestos!$B$7 | E5: =B5/B18
A6: 02 ENVOLVENTE: FACHADA Y MEDIANERA | B6: ='Presupuesto vivienda'!J11 | C6: ='Presupuesto vivienda'!K11 | D6: =B6/Supuestos!$B$7 | E6: =B6/B18
A7: 03 CUBIERTA PLANA | B7: ='Presupuesto vivienda'!J18 | C7: ='Presupuesto vivienda'!K18 | D7: =B7/Supuestos!$B$7 | E7: =B7/B18
A8: 04 SUELOS Y FORJADO ENTRE PLANTAS | B8: ='Presupuesto vivienda'!J30 | C8: ='Presupuesto vivienda'!K30 | D8: =B8/Supuestos!$B$7 | E8: =B8/B18
A9: 05 ELECTRICIDAD Y TELECOMUNICACIONES | B9: ='Presupuesto vivienda'!J35 | C9: ='Presupuesto vivienda'!K35 | D9: =B9/Supuestos!$B$7 | E9: =B9/B18
A10: 06 FONTANERÍA, SANEAMIENTO Y SANITARIOS | B10: ='Presupuesto vivienda'!J39 | C10: ='Presupuesto vivienda'!K39 | D10: =B10/Supuestos!$B$7 | E10: =B10/B18
A11: 07 CLIMATIZACIÓN, ACS Y VENTILACIÓN | B11: ='Presupuesto vivienda'!J50 | C11: ='Presupuesto vivienda'!K50 | D11: =B11/Supuestos!$B$7 | E11: =B11/B18
A12: 08 CARPINTERÍA EXTERIOR | B12: ='Presupuesto vivienda'!J55 | C12: ='Presupuesto vivienda'!K55 | D12: =B12/Supuestos!$B$7 | E12: =B12/B18
A13: 09 ACABADO EXTERIOR DE FACHADA | B13: ='Presupuesto vivienda'!J59 | C13: ='Presupuesto vivienda'!K59 | D13: =B13/Supuestos!$B$7 | E13: =B13/B18
A14: 10 TABIQUERÍA, TECHOS Y PINTURA | B14: ='Presupuesto vivienda'!J61 | C14: ='Presupuesto vivienda'!K61 | D14: =B14/Supuestos!$B$7 | E14: =B14/B18
A15: 11 PAVIMENTOS Y ESCALERA | B15: ='Presupuesto vivienda'!J69 | C15: ='Presupuesto vivienda'!K69 | D15: =B15/Supuestos!$B$7 | E15: =B15/B18
A16: 12 CARPINTERÍA INTERIOR | B16: ='Presupuesto vivienda'!J74 | C16: ='Presupuesto vivienda'!K74 | D16: =B16/Supuestos!$B$7 | E16: =B16/B18
A17: 13 TRANSPORTE, MONTAJE Y ENTREGA | B17: ='Presupuesto vivienda'!J78 | C17: ='Presupuesto vivienda'!K78 | D17: =B17/Supuestos!$B$7 | E17: =B17/B18
A18: PRECIO DE FÁBRICA POR VIVIENDA | B18: =SUM(B5:B17) | C18: =SUM(C5:C17) | D18: =B18/Supuestos!$B$7
A19: Margen de la empresa vendedora (gastos generales + beneficio) | B19: =B18*Supuestos!$B$46 | C19: =C18*Supuestos!$B$46
A20: PRECIO DE VENTA AL PROMOTOR: VIVIENDA PILOTO (sin IVA) | B20: =B18+B19 | C20: =C18+C19 | D20: =B20/Supuestos!$B$7
A22: SERIE COMPLETA: 16 VIVIENDAS
A23: Concepto | B23: Unidades | C23: Precio unitario | D23: Importe
A24: Viviendas pareadas | B24: =Supuestos!$B$43 | C24: =B20*(1-Supuestos!$B$45) | D24: =B24*C24
A25: Viviendas independientes | B25: =Supuestos!$B$44 | C25: =C20*(1-Supuestos!$B$45) | D25: =B25*C25
A26: TOTAL SERIE (sin IVA) | B26: =B24+B25 | D26: =D24+D25
A27: €/m² construido medio de la serie | D27: =D26/(B26*Supuestos!$B$7)
A28: Precio de serie = precio piloto con el descuento por volumen de «Supuestos». Aplicado a todo el precio: es una simplificación.
A30: QUÉ INCLUYE Y QUÉ NO
A31: INCLUYE | B31: Vivienda terminada en fábrica según la memoria de calidades: estructura, envolvente, cubierta, instalaciones (electricidad, fontanería, suelo radiante, aerotermia, ventilación), carpinterías, acabados y sanitarios. Transporte, grúa, montaje y limpieza.
A32: NO INCLUYE | B32: Cimentación (losa o zapatas) y soleras. Acometidas y urbanización. Terraza y jardín de planta baja, cerramientos de parcela, garaje y zonas comunes (piscina, huerto, jardín).
A33: NO INCLUYE | B33: Muebles de cocina (el dossier la entrega sin amueblar), electrodomésticos, piscina privada.
A34: NO INCLUYE | B34: Proyecto, dirección facultativa, OCT, seguro decenal, licencias, tasas, estudio geotécnico, ensayos y coordinación de seguridad y salud.
A35: REFERENCIA | B35: Obra in situ en Menorca Pino 2024 (cimentación, urbanización, acometidas y cerramiento): 89.194 € para 165 m² (≈ 541 €/m²). Solo orientativo: Menorca no es la Sierra de Madrid.
A38: PUNTOS A CERRAR ANTES DE ENVIAR LA OFERTA
A39: 1. Sistema constructivo: la memoria prevé estructura de hormigón y fachadas con cámara. El promotor tiene que aceptar el cambio a módulo de acero + panel Tabihaus, y el proyecto de ejecución, el OCT y el seguro decenal tienen que admitirlo.
A40: 2. Acero: estimado a 90 kg/m². Con dos plantas, el cálculo de estructura puede subirlo. Pedir a los soldadores el precio actual del kg soldado (en 2024 costó entre 3 y 4,9 €/kg y se vendió a 2,80).
A41: 3. Pedir precio a Tabihaus (paneles 66, 81 y 136 mm, y 8+20+8) y a un carpintero de PVC con persiana monoblock: son las partidas más grandes después de la estructura.
A42: 4. Medidas: ancho y fondo medidos en un plano de presentación. Confirmar con el proyecto básico y ver si los módulos de 2,67 m encajan con la distribución (salón de 28,7 m² y escalera).
A43: 5. Ubicación de la fábrica en 2026: el transporte está calculado desde Seseña.

Sheet Supuestos
A1: NÉVOLA: chalet tipo A pasado a sistema modular (datos de partida)
A2: Amarillo = dato que puedes cambiar. Todo el presupuesto se recalcula a partir de esta hoja.
A4: Concepto | B4: Valor | C4: Origen / comentario
A5: Superficie construida planta baja (m²) | B5: 74.58 | C5: Dossier comercial, vivienda tipo A (pág. 13)
A6: Superficie construida planta primera (m²) | B6: 73.72 | C6: Dossier comercial, vivienda tipo A
A7: TOTAL SUPERFICIE CONSTRUIDA (m²) | B7: =B5+B6 | C7: 148,30 m²; con terrazas, 182,10 m²
A8: Superficie útil (m²) | B8: 123.71 | C8: Suma de estancias del plano: 62,19 en planta baja + 61,52 en planta primera
A9: Terraza de planta primera (m²) | B9: 9.59 | C9: La terraza de planta baja (24,48 m²) es obra in situ: queda fuera
A10: Ancho de la vivienda (m) | B10: 8 | C10: Medido en el plano con la escala gráfica. Comprobar con el proyecto
A11: Fondo de la vivienda (m) | B11: 9.4 | C11: Medido en el plano con la escala gráfica (8,0 × 9,4 ≈ 75 m² por planta)
A12: Módulos por planta | B12: 3 | C12: Módulos de ≈2,67 m de ancho: transporte normal sin escolta
A13: Plantas | B13: 2
A14: Nº de módulos por vivienda | B14: =B12*B13
A15: Ancho de cada módulo (m) | B15: =B10/B12
A16: Altura exterior de módulo (m) | B16: 3 | C16: Pilar de 2,55 m más vigas de suelo y techo (sistema Tini)
A17: Perímetro de fachada por planta (m) | B17: =2*(B10+B11)
A18: Fachada bruta, todas las caras (m²) | B18: =B17*B16*B13
A19: % de huecos sobre fachada | B19: 0.17 | C19: Estimado con los planos: grandes ventanales al salón y a los dormitorios
A20: Superficie de huecos / carpintería (m²) | B20: =B18*B19
A21: Medianera en pareados (m²) | B21: =B11*B16*B13 | C21: Lleva panel, pero no acabado exterior. Doble placa por protección contra incendios
A22: Ratio de acero (kg por m² construido) | B22: 90 | C22: El Boalo 91 kg/m², Menorca 84, Sotopinilla 79. Dos plantas: se toma el alto
A23: Acero estructural (kg) | B23: =B22*B7 | C23: Hasta tener el cálculo de estructura
A24: Tabiquería interior (m² de tabique por m² construido) | B24: 0.9 | C24: Menorca Pino: 0,90
A25: Tabiquería interior (m²) | B25: =B24*B7
A26: Zonas húmedas con gres (m²) | B26: 27.13 | C26: Cocina 8,49 + lavadero 3,98 + baños 3,65 + 3,89 + 7,12
A27: Escalera, superficie en planta (m²) | B27: 6.95 | C27: 2,29 + 4,66
A28: Tarima laminada AC5 (m²) | B28: =B8-B26-B27 | C28: Superficie útil menos zonas húmedas y escalera
A29: Alicatado de baños y frente de cocina (m²) | B29: 56 | C29: Estimado: 2 baños × 20 m² + aseo 12 m² + cocina 4 m²
A30: Puertas interiores de paso | B30: 10 | C30: Contadas en el plano
A31: Baños completos | B31: 2 | C31: Baño 2 con bañera; baño principal con ducha y lavabo doble
A32: Aseos | B32: 1 | C32: Baño 1 de planta baja, con ducha
A33: Canalón (m) | B33: =B10*2
A34: Albardilla / remate de cubierta (m) | B34: =B17
A35: Barandilla de vidrio, terraza de planta primera (m) | B35: 8 | C35: Estimado en el plano
A36: Pliegues y remates de huecos (m) | B36: 60 | C36: Estimado a partir de la superficie de huecos
A37: Rodapié (m) | B37: 110 | C37: Perímetro de las estancias secas, estimado
A38: Actualización de precios 2024→2026 (todas las partidas) | B38: 0.12 | C38: Costes de construcción residencial: +5,46 % en 2025 (ACR); +3,5 % interanual en abril de 2026, máximo histórico (Banco de España); energía y combustible disparados en 2026. Desde mediados de 2024 salen unos 11 puntos: se redondea a 12 %
A39: Horas de montaje in situ por vivienda | B39: 192 | C39: Supuesto: 3 operarios × 8 días (uniones, juntas, remates, conexión de instalaciones)
A40: Precio hora de montaje (€/h) | B40: 40 | C40: Coste completo de fábrica 2024 ≈ 40 €/h. En 2024 se vendía a 30 €/h (por debajo del coste)
A41: Transporte por módulo (€) | B41: 900 | C41: Sotopinilla 2024: 780 €/módulo (Moreno). Guadalix: <100 km de Seseña
...

Sheet Presupuesto vivienda
A1: PRESUPUESTO POR PARTIDAS: CHALET TIPO A NÉVOLA EN SISTEMA MODULAR (fabricación, transporte y montaje)
A2: Precio 2026 = precio base 2024 × (1 + actualización), en todas las partidas. Fondo naranja = partida sin referencia en el banco: precio base ESTIMADO, pedir oferta a proveedor.
A3: La cantidad «independiente» solo cambia en la medianera: la independiente tiene cuatro fachadas con acabado.
A5: Código | B5: Descripción | C5: Ud | D5: Medición | E5: Cant. pareada | F5: Cant. independiente | G5: Precio base 2024 | H5: Referencia del precio | I5: PRECIO 2026 | J5: Importe pareada | K5: Importe independiente
A6: 01 | B6: ESTRUCTURA METÁLICA DE MÓDULOS | J6: =SUM(J7:J10) | K6: =SUM(K7:K10)
A7: EST | B7: Acero S275JR en pilares, vigas, correas, refuerzos y pletinas, soldado en fábrica | C7: kg | D7: Ratio kg/m² × m² construidos | E7: =Supuestos!$B$23 | F7: =E7 | G7: 2.8 | H7: Todos los proyectos 2024: 2,80 €/kg | I7: =G7*(1+Supuestos!$B$38) | J7: =E7*I7 | K7: =F7*I7
A8: EST_PN_GIM | B8: Granallado e imprimación | C8: kg | D8: = acero | E8: =Supuestos!$B$23 | F8: =E8 | G8: 0.11 | H8: Fenwick, Sotopinilla, El Boalo | I8: =G8*(1+Supuestos!$B$38) | J8: =E8*I8 | K8: =F8*I8
A9: EST_PN_PPV | B9: Pintura de poliuretano (tratamiento C2-C3) | C9: kg | D9: = acero | E9: =Supuestos!$B$23 | F9: =E9 | G9: 0.1 | H9: Sotopinilla 0,10 · Fenwick 0,15 | I9: =G9*(1+Supuestos!$B$38) | J9: =E9*I9 | K9: =F9*I9
A10: EST_PL_AG | B10: Agarraderas de izado (4 por módulo) | C10: u | D10: 4 × nº de módulos | E10: =4*Supuestos!$B$14 | F10: =E10 | G10: 4.48 | H10: Fenwick, Menorca | I10: =G10*(1+Supuestos!$B$38) | J10: =E10*I10 | K10: =F10*I10
A11: 02 | B11: ENVOLVENTE: FACHADA Y MEDIANERA | J11: =SUM(J12:J17) | K11: =SUM(K12:K17)
A12: FAC_SAN_TAH | B12: Panel sándwich Tabihaus 8+50+8 (66 mm) en fachada y medianera | C12: m² | D12: Fachada bruta − huecos | E12: =(Supuestos!$B$18-Supuestos!$B$20) | F12: =E12 | G12: 75 | H12: El Boalo 75 €/m² · Menorca oct-24 82,42 €/m² | I12: =G12*(1+Supuestos!$B$38) | J12: =E12*I12 | K12: =F12*I12
A13: FAC_ATR | B13: Aislamiento térmico reflexivo | C13: m² | D13: = panel de fachada | E13: =(Supuestos!$B$18-Supuestos!$B$20) | F13: =E13 | G13: 11.25 | H13: Todos los proyectos | I13: =G13*(1+Supuestos!$B$38) | J13: =E13*I13 | K13: =F13*I13
A14: FAC_PET80 | B14: Aislamiento de PET reciclado de 80 mm | C14: m² | D14: = panel de fachada | E14: =(Supuestos!$B$18-Supuestos!$B$20) | F14: =E14 | G14: 15.7 | H14: Todos los proyectos | I14: =G14*(1+Supuestos!$B$38) | J14: =E14*I14 | K14: =F14*I14
A15: FAC_U46 | B15: Perfilería U 46 mm cada 60 cm (trasdosado interior) | C15: m² | D15: = panel de fachada | E15: =(Supuestos!$B$18-Supuestos!$B$20) | F15: =E15 | G15: 22 | H15: Todos los proyectos | I15: =G15*(1+Supuestos!$B$38) | J15: =E15*I15 | K15: =F15*I15
A16: TAB_PYL13 | B16: Placa de yeso laminado de 13 mm en trasdosado de fachada | C16: m² | D16: = panel de fachada | E16: =(Supuestos!$B$18-Supuestos!$B$20) | F16: =E16 | G16: 13.56 | H16: Banco (TAB_PYL13) | I16: =G16*(1+Supuestos!$B$38) | J16: =E16*I16 | K16: =F16*I16
A17: TAB_2PLA | B17: Doble placa en medianera (protección contra incendios entre viviendas) | C17: m² | D17: Solo pareadas | E17: =Supuestos!$B$21 | F17: =0 | G17: 27.12 | H17: Menorca (TAB_2PLA) | I17: =G17*(1+Supuestos!$B$38) | J17: =E17*I17 | K17: =F17*I17
A18: 03 | B18: CUBIERTA PLANA | J18: =SUM(J19:J29) | K18: =SUM(K19:K29)
A19: CUB_SAN_TAH | B19: Panel sándwich Tabihaus 8+65+8 (81 mm) de cubierta | C19: m² | D19: Planta primera | E19: =Supuestos!$B$6 | F19: =E19 | G19: 65 | H19: El Boalo 65 · Menorca oct-24 58,37 | I19: =G19*(1+Supuestos!$B$38) | J19: =E19*I19 | K19: =F19*I19
A20: CUB_ATR | B20: Aislamiento térmico reflexivo | C20: m² | D20: = cubierta | E20: =Supuestos!$B$6 | F20: =E20 | G20: 11.25 | H20: Todos los proyectos | I20: =G20*(1+Supuestos!$B$38) | J20: =E20*I20 | K20: =F20*I20
A21: CUB_XPS60 | B21: Aislamiento XPS 60 mm | C21: m² | D21: = cubierta | E21: =Supuestos!$B$6 | F21: =E21 | G21: 10 | H21: Todos los proyectos | I21: =G21*(1+Supuestos!$B$38) | J21: =E21*I21 | K21: =F21*I21
A22: CUB_PET40 | B22: Aislamiento de PET reciclado 40 mm | C22: m² | D22: = cubierta | E22: =Supuestos!$B$6 | F22: =E22 | G22: 10 | H22: Todos los proyectos | I22: =G22*(1+Supuestos!$B$38) | J22: =E22*I22 | K22: =F22*I22
A23: CUB_TAB | B23: Impermeabilización: tela asfáltica bicapa | C23: m² | D23: = cubierta | E23: =Supuestos!$B$6 | F23: =E23 | G23: 36 | H23: Todos los proyectos | I23: =G23*(1+Supuestos!$B$38) | J23: =E23*I23 | K23: =F23*I23
A24: CUB_GRA | B24: Acabado de grava en zona no transitable | C24: m² | D24: Cubierta − terraza | E24: =Supuestos!$B$6-Supuestos!$B$9 | F24: =E24 | G24: 12 | H24: ESTIMADO (no está en el banco) | I24: =G24*(1+Supuestos!$B$38) | J24: =E24*I24 | K24: =F24*I24
A25: CUB_CAN | B25: Canalón de chapa plegada de 2 mm | C25: m | D25: Supuestos | E25: =Supuestos!$B$33 | F25: =E25 | G25: 38 | H25: Todos los proyectos | I25: =G25*(1+Supuestos!$B$38) | J25: =E25*I25 | K25: =F25*I25
A26: CUB_GAR | B26: Gárgola metálica con pieza de EPDM | C26: u | D26: 3 por vivienda | E26: =3 | F26: =E26 | G26: 52 | H26: Todos los proyectos | I26: =G26*(1+Supuestos!$B$38) | J26: =E26*I26 | K26: =F26*I26
A27: CUB_ALB | B27: Albardilla de chapa plegada galvanizada de 2 mm | C27: m | D27: Perímetro de cubierta | E27: =Supuestos!$B$34 | F27: =E27 | G27: 25.05 | H27: Todos los proyectos | I27: =G27*(1+Supuestos!$B$38) | J27: =E27*I27 | K27: =F27*I27
A28: TER_GRES | B28: Gres exterior antideslizante en terraza de planta primera | C28: m² | D28: Supuestos | E28: =Supuestos!$B$9 | F28: =E28 | G28: 45 | H28: Banco (PAV_SOCE, solado cerámico) | I28: =G28*(1+Supuestos!$B$38) | J28: =E28*I28 | K28: =F28*I28
A29: TER_BAR | B29: Barandilla de vidrio de seguridad en terraza | C29: m | D29: Supuestos | E29: =Supuestos!$B$35 | F29: =E29 | G29: 350 | H29: ESTIMADO (en el banco solo hay malla: 217,80 €/m) | I29: =G29*(1+Supuestos!$B$38) | J29: =E29*I29 | K29: =F29*I29
A30: 04 | B30: SUELOS Y FORJADO ENTRE PLANTAS | J30: =SUM(J31:J34) | K30: =SUM(K31:K34)
A31: SUE_SAN_136 | B31: Panel sándwich Tabihaus 8+120+8 (136 mm), suelo de planta baja | C31: m² | D31: Planta baja | E31: =Supuestos!$B$5 | F31: =E31 | G31: 99 | H31: El Boalo 99 · Menorca oct-24 86,09 | I31: =G31*(1+Supuestos!$B$38) | J31: =E31*I31 | K31: =F31*I31
A32: SUE_SAN_81 | B32: Panel sándwich Tabihaus 8+65+8, suelo de módulos de planta primera | C32: m² | D32: Planta primera | E32: =Supuestos!$B$6 | F32: =E32 | G32: 65 | H32: El Boalo (SUE 8+65+8) 65 | I32: =G32*(1+Supuestos!$B$38) | J32: =E32*I32 | K32: =F32*I32
A33: SUE_TEC_40 | B33: Panel Tabihaus 8+20+8, techo de módulos de planta baja | C33: m² | D33: Planta baja | E33: =Supuestos!$B$5 | F33: =E33 | G33: 50 | H33: ESTIMADO: coste de lista 40 €/m² (Mahón) + margen | I33: =G33*(1+Supuestos!$B$38) | J33: =E33*I33 | K33: =F33*I33
A34: SUE_ATR | B34: Aislamiento térmico reflexivo bajo forjado | C34: m² | D34: Planta baja | E34: =Supuestos!$B$5 | F34: =E34 | G34: 11.25 | H34: Menorca, El Boalo | I34: =G34*(1+Supuestos!$B$38) | J34: =E34*I34 | K34: =F34*I34
A35: 05 | B35: ELECTRICIDAD Y TELECOMUNICACIONES | J35: =SUM(J36:J38) | K35: =SUM(K36:K38)
A36: ELE_M2 | B36: Instalación eléctrica completa (cuadro, circuitos, mecanismos Niessen o similar, iluminación, TV y datos en estancias) | C36: m² | D36: m² construidos | E36: =Supuestos!$B$7 | F36: =E36 | G36: 55 | H36: Ratio: Sotopinilla 61 €/m² · Menorca 39 €/m² (sin el error de la toma de tierras) | I36: =G36*(1+Supuestos!$B$38) | J36: =E36*I36 | K36: =F36*I36
A37: ELE_POR | B37: Portero automático | C37: u | D37: 1 | E37: =1 | F37: =E37 | G37: 350 | H37: ESTIMADO | I37: =G37*(1+Supuestos!$B$38) | J37: =E37*I37 | K37: =F37*I37
A38: ELE_VE | B38: Preinstalación de punto de recarga de vehículo eléctrico | C38: u | D38: 1 | E38: =1 | F38: =E38 | G38: 450 | H38: ESTIMADO | I38: =G38*(1+Supuestos!$B$38) | J38: =E38*I38 | K38: =F38*I38
A39: 06 | B39: FONTANERÍA, SANEAMIENTO Y SANITARIOS | J39: =SUM(J40:J49) | K39: =SUM(K40:K49)
A40: BAN_INS | B40: Instalación completa de fontanería y saneamiento por baño o aseo | C40: u | D40: Baños + aseo | E40: =Supuestos!$B$31+Supuestos!$B$32 | F40: =E40 | G40: 494 | H40: Todos los proyectos | I40: =G40*(1+Supuestos!$B$38) | J40: =E40*I40 | K40: =F40*I40
A41: 09TLAV | B41: Tomas de agua y desagüe: cocina, lavadora, secadora y pila de lavadero | C41: u | D41: 4 tomas | E41: =4 | F41: =E41 | G41: 75 | H41: Menorca (toma de lavadora) | I41: =G41*(1+Supuestos!$B$38) | J41: =E41*I41 | K41: =F41*I41
...
